Workbook

Sheet 畅想结算中心
A1: 发票号码 | B1: 财务期间 | C1: 客户编号 | D1: 渠道类型 | E1: 畅想部门 | F1: 畅想组别 | G1: 销品公司 | H1: 分公司 | I1: 销品小组 | J1: 一级目录 | K1: 二级目录 | L1: 三级目录 | M1: SPU | N1: 产品编号 | O1: 产品经理 | P1: 开发类型 | Q1: 外销币种 | R1: USD汇率 | S1: 应收货款 | T1: 应收货款（美元） | U1: 信保费用 | V1: 银行费用 | W1: 佣金 | X1: 采购金额（含税销售） | Y1: 减：退税额 | Z1: 出运包干费 | AA1: 单证费 | AB1: 海运及保险费 | AC1: 国内其他费用 | AD1: 仓储费 | AE1: 验货费 | AF1: 包装设计费 | AG1: 毛利
A2: HSA25J004-A | B2: 46047 | C2: 波兰749 | D2: 渠道商 | E2: 昊特赛八公司 | F2: 办公室 | H2: 市场七一司 | I2: 业务办公室 | J2: 露营和远足 | K2: 户外家具 | L2: 庭院吊篮 | N2: PO-OF5001-002 | O2: 王柯飞 | P2: 外部引进 | Q2: USD | R2: 6.96 | S2: 5140.8 | T2: 5140.8 | U2: 35.99 | V2: 50 | W2: 0 | X2: 34272 | Y2: 3942.8 | Z2: 2909.65 | AA2: 0 | AB2: 0 | AC2: 0 | AD2: 0 | AE2: 0 | AF2: 0 | AG2: =(T2-U2-V2-W2)*R2-X2+Y2-Z2-AA2-AB2-AC2-AD2-AE2-AF2 -> 1942.6276 | AH2: =IF(ISNUMBER(MATCH(A2,'畅想出运数据（核算明细导出）'!$C$2:$C$484,0)),"有","无") -> 有
A3: HSA25J007-2 | B3: 46047 | C3: 波兰749 | D3: 渠道商 | E3: 昊特赛三公司 | F3: 办公室 | H3: 市场七一司 | I3: 业务办公室 | J3: 户外骑行和滑板 | K3: 自行车 | L3: 自行车铃铛 | N3: PO-CS3001-004 | O3: 王柯飞 | P3: 外部引进 | Q3: USD | R3: 6.96 | S3: 0 | T3: 0 | U3: 0 | V3: 0 | W3: 0 | X3: 3526.4 | Y3: 405.69 | Z3: 495.98 | AA3: 0 | AB3: 0 | AC3: 0 | AD3: 0 | AE3: 0 | AF3: 0 | AG3: =(T3-U3-V3-W3)*R3-X3+Y3-Z3-AA3-AB3-AC3-AD3-AE3-AF3 -> -3616.69 | AH3: =IF(ISNUMBER(MATCH(A3,'畅想出运数据（核算明细导出）'!$C$2:$C$484,0)),"有","无") -> 有
A4: HSA25J007-2 | B4: 46047 | C4: 波兰749 | D4: 渠道商 | E4: 昊特赛三公司 | F4: 办公室 | H4: 市场七一司 | I4: 业务办公室 | J4: 园林装饰 | K4: 喷泉及其他园林装饰品 | L4: 风车 | N4: PO-CS3001-001 | O4: 王柯飞 | P4: 外部引进 | Q4: USD | R4: 6.96 | S4: 1216 | T4: 1216 | U4: 8.51 | V4: 50 | W4: 0 | X4: 4803.2 | Y4: 552.58 | Z4: 638.26 | AA4: 0 | AB4: 0 | AC4: 0 | AD4: 0 | AE4: 0 | AF4: 0 | AG4: =(T4-U4-V4-W4)*R4-X4+Y4-Z4-AA4-AB4-AC4-AD4-AE4-AF4 -> 3167.2504 | AH4: =IF(ISNUMBER(MATCH(A4,'畅想出运数据（核算明细导出）'!$C$2:$C$484,0)),"有","无") -> 有
A5: HSA25Y007-1 | B5: 46047 | C5: 波兰749 | D5: 渠道商 | E5: 昊特赛一公司 | F5: 客户第一组 | H5: 市场七一司 | I5: 客户第二组 | J5: DIY玩具 | K5: 其他DIY玩具 | L5: 其他常规DIY玩具 | M5: 0C003 | N5: OC003-MQ-brown | O5: 原柯冬浩 | P5: 外部引进 | Q5: USD | R5: 6.98 | S5: 1108.8 | T5: 1108.8 | U5: 7.76 | V5: 50 | W5: 0 | X5: 7358.4 | Y5: 846.54 | Z5: 1829.26 | AA5: 0 | AB5: 0 | AC5: 0 | AD5: 0 | AE5: 0 | AF5: 0 | AG5: =(T5-U5-V5-W5)*R5-X5+Y5-Z5-AA5-AB5-AC5-AD5-AE5-AF5 -> -1004.8608 | AH5: =IF(ISNUMBER(MATCH(A5,'畅想出运数据（核算明细导出）'!$C$2:$C$484,0)),"有","无") -> 有
A6: HSA25D001-2,HSA25D006-2 | B6: 46047 | C6: 波兰749 | D6: 渠道商 | E6: 昊特赛一公司 | F6: 客户第一组 | H6: 市场七一司 | I6: 客户第二组 | J6: 工艺陶瓷 | K6: 陶瓷工艺品 | L6: 常规陶瓷工艺品 | N6: GD-PC200-1023 | O6: 钟 琪 | P6: 外部引进 | Q6: USD | R6: 6.97 | S6: 1900.8 | T6: 1900.8 | U6: 13.31 | V6: 41.27 | W6: 0 | X6: 12960 | Y6: 1032.21 | Z6: 1162.05 | AA6: 0 | AB6: 0 | AC6: 0 | AD6: 0 | AE6: 0 | AF6: 0 | AG6: =(T6-U6-V6-W6)*R6-X6+Y6-Z6-AA6-AB6-AC6-AD6-AE6-AF6 -> -221.6866 | AH6: =IF(ISNUMBER(MATCH(A6,'畅想出运数据（核算明细导出）'!$C$2:$C$484,0)),"有","无") -> 有
A7: HSA25D001-2,HSA25D006-2 | B7: 46047 | C7: 波兰749 | D7: 渠道商 | E7: 昊特赛一公司 | F7: 客户第一组 | H7: 市场七一司 | I7: 客户第二组 | J7: 工艺陶瓷 | K7: 陶瓷工艺品 | L7: 常规陶瓷工艺品 | N7: GD-PC100-1001 | O7: 钟 琪 | P7: 外部引进 | Q7: USD | R7: 6.97 | S7: 402 | T7: 402 | U7: 2.81 | V7: 8.73 | W7: 0 | X7: 2640 | Y7: 210.27 | Z7: 497.16 | AA7: 0 | AB7: 0 | AC7: 0 | AD7: 0 | AE7: 0 | AF7: 0 | AG7: =(T7-U7-V7-W7)*R7-X7+Y7-Z7-AA7-AB7-AC7-AD7-AE7-AF7 -> -205.3838 | AH7: =IF(ISNUMBER(MATCH(A7,'畅想出运数据（核算明细导出）'!$C$2:$C$484,0)),"有","无") -> 有
A8: HSA25J006 | B8: 46047 | C8: 波兰749 | D8: 渠道商 | E8: 昊特赛一公司 | F8: 客户第二组 | H8: 市场七一司 | I8: 客户第二组 | J8: 专用材料 | K8: 隔热材料 | L8: 常规隔热材料 | N8: BF-SM3001-002 | O8: 王柯飞 | P8: 外部引进 | Q8: USD | R8: 6.98 | S8: 485 | T8: 485 | U8: 3.39 | V8: 24.04 | W8: 0 | X8: 2500 | Y8: 287.61 | Z8: 504.89 | AA8: 0 | AB8: 0 | AC8: 0 | AD8: 0 | AE8: 0 | AF8: 0 | AG8: =(T8-U8-V8-W8)*R8-X8+Y8-Z8-AA8-AB8-AC8-AD8-AE8-AF8 -> 476.5586 | AH8: =IF(ISNUMBER(MATCH(A8,'畅想出运数据（核算明细导出）'!$C$2:$C$484,0)),"有","无") -> 有
A9: HSA25J006 | B9: 46047 | C9: 波兰749 | D9: 渠道商 | E9: 昊特赛一公司 | F9: 客户第二组 | H9: 市场七一司 | I9: 客户第二组 | J9: 专用材料 | K9: 隔热材料 | L9: 常规隔热材料 | N9: BF-SM3001-001 | O9: 王柯飞 | P9: 外部引进 | Q9: USD | R9: 6.98 | S9: 523.8 | T9: 523.8 | U9: 3.67 | V9: 25.96 | W9: 0 | X9: 2700 | Y9: 310.62 | Z9: 605.86 | AA9: 0 | AB9: 0 | AC9: 0 | AD9: 0 | AE9: 0 | AF9: 0 | AG9: =(T9-U9-V9-W9)*R9-X9+Y9-Z9-AA9-AB9-AC9-AD9-AE9-AF9 -> 454.0666 | AH9: =IF(ISNUMBER(MATCH(A9,'畅想出运数据（核算明细导出）'!$C$2:$C$484,0)),"有","无") -> 有
A10: HSA25J010-1 | B10: 46047 | C10: 波兰749 | D10: 渠道商 | E10: 昊特赛一公司 | F10: 客户第二组 | H10: 市场七一司 | I10: 客户第二组 | J10: 家庭收纳 | K10: 收纳容器 | L10: 收纳盒 | N10: HS-HO100-1001 | O10: 钟 琪 | P10: 外部引进 | Q10: USD | R10: 6.96 | S10: 1229.76 | T10: 1229.76 | U10: 8.61 | V10: 50 | W10: 0 | X10: 8064 | Y10: 927.72 | Z10: 672.98 | AA10: 0 | AB10: 0 | AC10: 0 | AD10: 0 | AE10: 0 | AF10: 0 | AG10: =(T10-U10-V10-W10)*R10-X10+Y10-Z10-AA10-AB10-AC10-AD10-AE10-AF10 -> 341.944 | AH10: =IF(ISNUMBER(MATCH(A10,'畅想出运数据（核算明细导出）'!$C$2:$C$484,0)),"有","无") -> 有
A11: HSC25X010-1 | B11: 46047 | C11: 美国5529 | D11: 渠道商 | E11: 昊特赛三公司 | F11: 客户第一组 | H11: 市场七三司 | I11: 客户第一组 | J11: 备菜工具 | K11: 刀具及配件 | L11: 水果刀 | N11: 99270 | O11: 黄家辉 | P11: 外部引进 | Q11: USD | R11: 6.95 | S11: 1434 | T11: 1434 | U11: 10.04 | V11: 8.14 | W11: 0 | X11: 8400 | Y11: 966.37 | Z11: 261.82 | AA11: 0 | AB11: 0 | AC11: 0 | AD11: 0 | AE11: 0 | AF11: 0 | AG11: =(T11-U11-V11-W11)*R11-X11+Y11-Z11-AA11-AB11-AC11-AD11-AE11-AF11 -> 2144.499 | AH11: =IF(ISNUMBER(MATCH(A11,'畅想出运数据（核算明细导出）'!$C$2:$C$484,0)),"有","无") -> 有
A12: HSC25X010-1 | B12: 46047 | C12: 美国5529 | D12: 渠道商 | E12: 昊特赛三公司 | F12: 客户第一组 | H12: 市场七三司 | I12: 客户第一组 | J12: 备菜工具 | K12: 刀具及配件 | L12: 切菜刀 | N12: 99272 | O12: 黄家辉 | P12: 自主研发 | Q12: USD | R12: 6.95 | S12: 1434 | T12: 1434 | U12: 10.04 | V12: 8.14 | W12: 0 | X12: 8700 | Y12: 1000.88 | Z12: 261.82 | AA12: 0 | AB12: 0 | AC12: 0 | AD12: 0 | AE12: 0 | AF12: 0 | AG12: =(T12-U12-V12-W12)*R12-X12+Y12-Z12-AA12-AB12-AC12-AD12-AE12-AF12 -> 1879.009 | AH12: =IF(ISNUMBER(MATCH(A12,'畅想出运数据（核算明细导出）'!$C$2:$C$484,0)),"有","无") -> 有
A13: HSC25X001-X002 | B13: 46047 | C13: 加拿大925 | D13: 渠道商 | E13: 昊特赛三公司 | F13: 客户第一组 | H13: 市场七三司 | I13: 客户第一组 | J13: 备菜工具 | K13: 洗菜及沥水篮 | L13: 沥水篮 | N13: 03-3104145 | O13: 黄家辉 | P13: 外部引进 | Q13: USD | R13: 6.96 | S13: 4230 | T13: 4230 | U13: 29.61 | V13: 33.1 | W13: 0 | X13: 28800 | Y13: 3313.27 | Z13: 2175.85 | AA13: 0 | AB13: 0 | AC13: 0 | AD13: 0 | AE13: 0 | AF13: 0 | AG13: =(T13-U13-V13-W13)*R13-X13+Y13-Z13-AA13-AB13-AC13-AD13-AE13-AF13 -> 1341.7584 | AH13: =IF(ISNUMBER(MATCH(A13,'畅想出运数据（核算明细导出）'!$C$2:$C$484,0)),"有","无") -> 有
A14: HSC25X010-1 | B14: 46047 | C14: 美国5529 | D14: 渠道商 | E14: 昊特赛三公司 | F14: 客户第一组 | H14: 市场七三司 | I14: 客户第一组 | J14: 备菜工具 | K14: 刀具及配件 | L14: 刀具套装 | N14: 99278 | O14: 黄家辉 | P14: 自主研发 | Q14: USD | R14: 6.95 | S14: 1995 | T14: 1995 | U14: 13.97 | V14: 11.32 | W14: 0 | X14: 12180 | Y14: 1401.24 | Z14: 320 | AA14: 0 | AB14: 0 | AC14: 0 | AD14: 0 | AE14: 0 | AF14: 0 | AG14: =(T14-U14-V14-W14)*R14-X14+Y14-Z14-AA14-AB14-AC14-AD14-AE14-AF14 -> 2590.7245 | AH14: =IF(ISNUMBER(MATCH(A14,'畅想出运数据（核算明细导出）'!$C$2:$C$484,0)),"有","无") -> 有
A15: HSC25X015-1 | B15: 46047 | C15: 以色列383 | D15: 品牌商 | E15: 昊特赛三公司 | F15: 客户第一组 | H15: 市场七三司 | I15: 客户第一组 | J15: 厨房清洁 | K15: 清洁工具 | L15: 厨房清洁海绵 | N15: 2376 | O15: 黄家辉 | P15: 外部引进 | Q15: USD | R15: 6.96 | S15: 5940 | T15: 5940 | U15: 41.58 | V15: 50 | W15: 0 | X15: 33480 | Y15: 3851.68 | Z15: 1900 | AA15: 0 | AB15: 0 | AC15: 0 | AD15: 0 | AE15: 0 | AF15: 0 | AG15: =(T15-U15-V15-W15)*R15-X15+Y15-Z15-AA15-AB15-AC15-AD15-AE15-AF15 -> 9176.6832 | AH15: =IF(ISNUMBER(MATCH(A15,'畅想出运数据（核算明细导出）'!$C$2:$C$484,0)),"有","无") -> 有
A16: HSC25X010-1 | B16: 46047 | C16: 美国5529 | D16: 渠道商 | E16: 昊特赛三公司 | F16: 客户第一组 | H16: 市场七三司 | I16: 客户第一组 | J16: 备菜工具 | K16: 刀具及配件 | L16: 切骨刀 | N16: 99276 | O16: 黄家辉 | P16: 自主研发 | Q16: USD | R16: 6.95 | S16: 1974 | T16: 1974 | U16: 13.82 | V16: 11.2 | W16: 0 | X16: 11790 | Y16: 1356.37 | Z16: 378.18 | AA16: 0 | AB16: 0 | AC16: 0 | AD16: 0 | AE16: 0 | AF16: 0 | AG16: =(T16-U16-V16-W16)*R16-X16+Y16-Z16-AA16-AB16-AC16-AD16-AE16-AF16 -> 2733.601 | AH16: =IF(ISNUMBER(MATCH(A16,'畅想出运数据（核算明细导出）'!$C$2:$C$484,0)),"有","无") -> 有
A17: HSC25X001-X002 | B17: 46047 | C17: 加拿大925 | D17: 渠道商 | E17: 昊特赛三公司 | F17: 客户第一组 | H17: 市场七三司 | I17: 客户第一组 | J17: 备菜工具 | K17: 洗菜及沥水篮 | L17: 沥水篮 | N17: 03-3092760 | O17: 黄家辉 | P17: 外部引进 | Q17: USD | R17: 6.96 | S17: 2160 | T17: 2160 | U17: 15.12 | V17: 16.9 | W17: 0 | X17: 13992 | Y17: 1609.7 | Z17: 857.15 | AA17: 0 | AB17: 0 | AC17: 0 | AD17: 0 | AE17: 0 | AF17: 0 | AG17: =(T17-U17-V17-W17)*R17-X17+Y17-Z17-AA17-AB17-AC17-AD17-AE17-AF17 -> 1571.2908 | AH17: =IF(ISNUMBER(MATCH(A17,'畅想出运数据（核算明细导出）'!$C$2:$C$484,0)),"有","无") -> 有
A18: HSC25X010-1 | B18: 46047 | C18: 美国5529 | D18: 渠道商 | E18: 昊特赛三公司 | F18: 客户第一组 | H18: 市场七三司 | I18: 客户第一组 | J18: 备菜工具 | K18: 刀具及配件 | L18: 切菜刀 | N18: 99274 | O18: 黄家辉 | P18: 自主研发 | Q18: USD | R18: 6.95 | S18: 1974 | T18: 1974 | U18: 13.82 | V18: 11.2 | W18: 0 | X18: 11790 | Y18: 1356.37 | Z18: 378.18 | AA18: 0 | AB18: 0 | AC18: 0 | AD18: 0 | AE18: 0 | AF18: 0 | AG18: =(T18-U18-V18-W18)*R18-X18+Y18-Z18-AA18-AB18-AC18-AD18-AE18-AF18 -> 2733.601 | AH18: =IF(ISNUMBER(MATCH(A18,'畅想出运数据（核算明细导出）'!$C$2:$C$484,0)),"有","无") -> 有
A19: HSB25M024-8 | B19: 46047 | C19: 英国2962 | D19: 渠道商 | E19: 昊特赛二公司 | F19: 办公室 | H19: 市场七二司 | I19: 业务办公室 | J19: 装扮玩具 | K19: 其他装扮玩具 | L19: 其他常规装扮玩具 | M19: 0D322 | N19: 0D322-PS001 | O19: 丁迎全 | P19: 外部引进 | Q19: USD | R19: 6.95 | S19: 376.32 | T19: 376.32 | U19: 2.63 | V19: 3.69 | W19: 11.29 | X19: 2916.48 | Y19: 335.52 | Z19: 0 | AA19: 0 | AB19: 0 | AC19: 0 | AD19: 0 | AE19: 0 | AF19: 0 | AG19: =(T19-U19-V19-W19)*R19-X19+Y19-Z19-AA19-AB19-AC19-AD19-AE19-AF19 -> -87.9255 | AH19: =IF(ISNUMBER(MATCH(A19,'畅想出运数据（核算明细导出）'!$C$2:$C$484,0)),"有","无") -> 有
A20: HSB25M024-11 | B20: 46047 | C20: 英国2962 | D20: 渠道商 | E20: 昊特赛二公司 | F20: 办公室 | H20: 市场七二司 | I20: 业务办公室 | J20: 装扮玩具 | K20: 其他装扮玩具 | L20: 其他常规装扮玩具 | M20: 0D322 | N20: 0D322-PS001 | O20: 丁迎全 | P20: 外部引进 | Q20: USD | R20: 6.96 | S20: 384 | T20: 384 | U20: 2.69 | V20: 3.79 | W20: 11.52 | X20: 2976 | Y20: 342.37 | Z20: 119.48 | AA20: 0 | AB20: 0 | AC20: 0 | AD20: 0 | AE20: 0 | AF20: 0 | AG20: =(T20-U20-V20-W20)*R20-X20+Y20-Z20-AA20-AB20-AC20-AD20-AE20-AF20 -> -205.75 | AH20: =IF(ISNUMBER(MATCH(A20,'畅想出运数据（核算明细导出）'!$C$2:$C$484,0)),"有","无") -> 有
A21: HSB25M024-10 | B21: 46047 | C21: 英国2962 | D21: 渠道商 | E21: 昊特赛二公司 | F21: 办公室 | H21: 市场七二司 | I21: 业务办公室 | J21: 装扮玩具 | K21: 其他装扮玩具 | L21: 其他常规装扮玩具 | M21: 0D322 | N21: 0D322-PS001 | O21: 丁迎全 | P21: 外部引进 | Q21: USD | R21: 6.96 | S21: 376.32 | T21: 376.32 | U21: 2.63 | V21: 3.61 | W21: 7.53 | X21: 2916.48 | Y21: 335.52 | Z21: 98.54 | AA21: 0 | AB21: 0 | AC21: 0 | AD21: 0 | AE21: 0 | AF21: 0 | AG21: =(T21-U21-V21-W21)*R21-X21+Y21-Z21-AA21-AB21-AC21-AD21-AE21-AF21 -> -156.152 | AH21: =IF(ISNUMBER(MATCH(A21,'畅想出运数据（核算明细导出）'!$C$2:$C$484,0)),"有","无") -> 有
A22: HSB25M024-8 | B22: 46047 | C22: 英国2962 | D22: 渠道商 | E22: 昊特赛二公司 | F22: 办公室 | H22: 市场七二司 | I22: 业务办公室 | J22: 运动休闲包 | K22: 沙滩包 | L22: 常规沙滩包 | M22: BB001 | N22: BB001-STB-1 | O22: 原柯冬浩 | P22: 外部引进 | Q22: USD | R22: 6.95 | S22: 4719.6 | T22: 4719.6 | U22: 33.04 | V22: 46.31 | W22: 141.59 | X22: 31050 | Y22: 3572.12 | Z22: 0 | AA22: 0 | AB22: 0 | AC22: 0 | AD22: 0 | AE22: 0 | AF22: 0 | AG22: =(T22-U22-V22-W22)*R22-X22+Y22-Z22-AA22-AB22-AC22-AD22-AE22-AF22 -> 3787.807 | AH22: =IF(ISNUMBER(MATCH(A22,'畅想出运数据（核算明细导出）'!$C$2:$C$484,0)),"有","无") -> 有
A23: HSB25M024-11 | B23: 46047 | C23: 英国2962 | D23: 渠道商 | E23: 昊特赛二公司 | F23: 办公室 | H23: 市场七二司 | I23: 业务办公室 | J23: 运动休闲包 | K23: 沙滩包 | L23: 常规沙滩包 | M23: BB001 | N23: BB001-STB-1 | O23: 原柯冬浩 | P23: 外部引进 | Q23: USD | R23: 6.96 | S23: 4681.6 | T23: 4681.6 | U23: 32.77 | V23: 46.21 | W23: 140.45 | X23: 30800 | Y23: 3543.36 | Z23: 2880.52 | AA23: 0 | AB23: 0 | AC23: 0 | AD23: 0 | AE23: 0 | AF23: 0 | AG23: =(T23-U23-V23-W23)*R23-X23+Y23-Z23-AA23-AB23-AC23-AD23-AE23-AF23 -> 919.5432 | AH23: =IF(ISNUMBER(MATCH(A23,'畅想出运数据（核算明细导出）'!$C$2:$C$484,0)),"有","无") -> 有
A24: HSB25M024-10 | B24: 46047 | C24: 英国2962 | D24: 渠道商 | E24: 昊特赛二公司 | F24: 办公室 | H24: 市场七二司 | I24: 业务办公室 | J24: 运动休闲包 | K24: 沙滩包 | L24: 常规沙滩包 | M24: BB001 | N24: BB001-STB-1 | O24: 原柯冬浩 | P24: 外部引进 | Q24: USD | R24: 6.96 | S24: 4833.6 | T24: 4833.6 | U24: 33.84 | V24: 46.39 | W24: 96.67 | X24: 31800 | Y24: 3658.41 | Z24: 2501.46 | AA24: 0 | AB24: 0 | AC24: 0 | AD24: 0 | AE24: 0 | AF24: 0 | AG24: =(T24-U24-V24-W24)*R24-X24+Y24-Z24-AA24-AB24-AC24-AD24-AE24-AF24 -> 1767.582 | AH24: =IF(ISNUMBER(MATCH(A24,'畅想出运数据（核算明细导出）'!$C$2:$C$484,0)),"有","无") -> 有
A25: HSB25M024-7 | B25: 46047 | C25: 英国2962 | D25: 渠道商 | E25: 昊特赛二公司 | F25: 办公室 | H25: 市场七二司 | I25: 业务办公室 | J25: 装扮玩具 | K25: 工具玩具 | L25: 常规工具玩具 | M25: TT003 | N25: TT003-FJWJ001 | O25: 丁迎全 | P25: 外部引进 | Q25: USD | R25: 6.94 | S25: 1725.89 | T25: 1725.89 | U25: 12.08 | V25: 10.02 | W25: 51.78 | X25: 10564.4 | Y25: 1215.37 | Z25: 1235.92 | AA25: 0 | AB25: 0 | AC25: 0 | AD25: 0 | AE25: 0 | AF25: 0 | AG25: =(T25-U25-V25-W25)*R25-X25+Y25-Z25-AA25-AB25-AC25-AD25-AE25-AF25 -> 879.9994 | AH25: =IF(ISNUMBER(MATCH(A25,'畅想出运数据（核算明细导出）'!$C$2:$C$484,0)),"有","无") -> 有
A26: HSB25M024-5 | B26: 46047 | C26: 英国2962 | D26: 渠道商 | E26: 昊特赛二公司 | F26: 办公室 | H26: 市场七二司 | I26: 业务办公室 | J26: 装扮玩具 | K26: 工具玩具 | L26: 常规工具玩具 | M26: TT003 | N26: TT003-FJWJ001 | O26: 丁迎全 | P26: 外部引进 | Q26: USD | R26: 6.96 | S26: 1689.6 | T26: 1689.6 | U26: 11.83 | V26: 12.38 | W26: 50.69 | X26: 10348.8 | Y26: 1190.57 | Z26: 1302.29 | AA26: 0 | AB26: 0 | AC26: 0 | AD26: 0 | AE26: 0 | AF26: 0 | AG26: =(T26-U26-V26-W26)*R26-X26+Y26-Z26-AA26-AB26-AC26-AD26-AE26-AF26 -> 777.792 | AH26: =IF(ISNUMBER(MATCH(A26,'畅想出运数据（核算明细导出）'!$C$2:$C$484,0)),"有","无") -> 有
A27: HSB25M024-2 | B27: 46047 | C27: 英国2962 | D27: 渠道商 | E27: 昊特赛二公司 | F27: 办公室 | H27: 市场七二司 | I27: 业务办公室 | J27: 装扮玩具 | K27: 工具玩具 | L27: 常规工具玩具 | M27: TT003 | N27: TT003-FJWJ001 | O27: 丁迎全 | P27: 外部引进 | Q27: USD | R27: 6.97 | S27: 1616 | T27: 1616 | U27: 11.31 | V27: 9.42 | W27: 0 | X27: 9898 | Y27: 1138.71 | Z27: 1090.17 | AA27: 0 | AB27: 0 | AC27: 0 | AD27: 0 | AE27: 0 | AF27: 0 | AG27: =(T27-U27-V27-W27)*R27-X27+Y27-Z27-AA27-AB27-AC27-AD27-AE27-AF27 -> 1269.5719 | AH27: =IF(ISNUMBER(MATCH(A27,'畅想出运数据（核算明细导出）'!$C$2:$C$484,0)),"有","无") -> 有
A28: HSB25M024-7 | B28: 46047 | C28: 英国2962 | D28: 渠道商 | E28: 昊特赛二公司 | F28: 办公室 | H28: 市场七二司 | I28: 业务办公室 | J28: 游泳装备 | K28: 游泳训练器材 | L28: 游泳圈 | M28: ST047 | N28: ST047-YQ-1 | O28: 丁迎全 | P28: 外部引进 | Q28: USD | R28: 6.94 | S28: 1664.26 | T28: 1664.26 | U28: 11.65 | V28: 9.67 | W28: 49.93 | X28: 9504 | Y28: 1093.38 | Z28: 266.02 | AA28: 0 | AB28: 0 | AC28: 0 | AD28: 0 | AE28: 0 | AF28: 0 | AG28: =(T28-U28-V28-W28)*R28-X28+Y28-Z28-AA28-AB28-AC28-AD28-AE28-AF28 -> 2378.8494 | AH28: =IF(ISNUMBER(MATCH(A28,'畅想出运数据（核算明细导出）'!$C$2:$C$484,0)),"有","无") -> 有
A29: HSB25M024-7 | B29: 46047 | C29: 英国2962 | D29: 渠道商 | E29: 昊特赛二公司 | F29: 办公室 | H29: 市场七二司 | I29: 业务办公室 | J29: 游泳装备 | K29: 游泳训练器材 | L29: 游泳圈 | M29: ST047 | N29: ST047-YQ-1 | O29: 丁迎全 | P29: 外部引进 | Q29: USD | R29: 6.94 | S29: 33.62 | T29: 33.62 | U29: 0.24 | V29: 0.2 | W29: 1.01 | X29: 192 | Y29: 22.09 | Z29: 5.37 | AA29: 0 | AB29: 0 | AC29: 0 | AD29: 0 | AE29: 0 | AF29: 0 | AG29: =(T29-U29-V29-W29)*R29-X29+Y29-Z29-AA29-AB29-AC29-AD29-AE29-AF29 -> 47.9798 | AH29: =IF(ISNUMBER(MATCH(A29,'畅想出运数据（核算明细导出）'!$C$2:$C$484,0)),"有","无") -> 有
A30: HSB25M024-4 | B30: 46047 | C30: 英国2962 | D30: 渠道商 | E30: 昊特赛二公司 | F30: 办公室 | H30: 市场七二司 | I30: 业务办公室 | J30: 游泳装备 | K30: 游泳训练器材 | L30: 游泳圈 | M30: ST047 | N30: ST047-YQ-1 | O30: 丁迎全 | P30: 外部引进 | Q30: USD | R30: 6.95 | S30: 1680 | T30: 1680 | U30: 11.76 | V30: 50 | W30: 0 | X30: 9600 | Y30: 1104.42 | Z30: 1035.34 | AA30: 0 | AB30: 0 | AC30: 0 | AD30: 0 | AE30: 0 | AF30: 0 | AG30: =(T30-U30-V30-W30)*R30-X30+Y30-Z30-AA30-AB30-AC30-AD30-AE30-AF30 -> 1715.848 | AH30: =IF(ISNUMBER(MATCH(A30,'畅想出运数据（核算明细导出）'!$C$2:$C$484,0)),"有","无") -> 有
... A49: HSB25E023-6 | B49: 46047 | C49: 英国2962 | D49: 渠道商 | E49: 昊特赛二公司 | F49: 客户第一组 | H49: 市场七二司 | I49: 客户第一组 | J49: 手工艺品及DIY玩具 | K49: 创意类及材料包 | L49: 其他常规DIY玩具 | M49: OD273 | N49: OD273-CN001 | O49: 丁迎全 | P49: 外部引进 | Q49: USD | R49: 6.96 | S49: 4180.8 | T49: 4180.8 | U49: 29.27 | V49: 50 | W49: 0 | X49: 26757.12 | Y49: 3078.25 | Z49: 0 | AA49: 0 | AB49: 0 | AC49: 0 | AD49: 0 | AE49: 0 | AF49: 0 | AG49: =(T49-U49-V49-W49)*R49-X49+Y49-Z49-AA49-AB49-AC49-AD49-AE49-AF49 -> 4867.7788 | AH49: =IF(ISNUMBER(MATCH(A49,'畅想出运数据（核算明细导出）'!$C$2:$C$484,0)),"有","无") -> 有
A50: Y25D0904-1 | B50: 46047 | C50: 美国0830 | D50: 品牌商 | E50: 昊特赛十公司 | F50: 办公室 | H50: 市场八十司 | I50: 业务办公室 | J50: 露营和远足 | K50: 户外家具 | L50: 户外折叠椅 | N50: HTS-W-8001 | O50: 王 进 | P50: 外部引进 | Q50: USD | R50: 6.97 | S50: 22368 | T50: 22368 | U50: 156.58 | V50: 50 | W50: 0 | X50: 97680 | Y50: 11237.52 | Z50: 49724.8 | AA50: 0 | AB50: 0 | AC50: 0 | AD50: 0 | AE50: 0 | AF50: 0 | AG50: =(T50-U50-V50-W50)*R50-X50+Y50-Z50-AA50-AB50-AC50-AD50-AE50-AF50 -> 18297.817 | AH50: =IF(ISNUMBER(MATCH(A50,'畅想出运数据（核算明细导出）'!$C$2:$C$484,0)),"有","无") -> 有
A51: HSJ25R005-2 | B51: 46047 | C51: 美国0830 | D51: 品牌商 | E51: 昊特赛十公司 | F51: 办公室 | H51: 市场八十司 | I51: 业务办公室 | J51: 露营和远足 | K51: 户外家具 | L51: 户外折叠椅 | N51: HTS-W-8001 | O51: 王 进 | P51: 外部引进 | Q51: USD | R51: 6.95 | S51: 3197.7 | T51: 3197.7 | U51: 22.38 | V51: 50 | W51: 0 | X51: 21374.1 | Y51: 2458.97 | Z51: 0 | AA51: 0 | AB51: 0 | AC51: 0 | AD51: 0 | AE51: 0 | AF51: 0 | AG51: =(T51-U51-V51-W51)*R51-X51+Y51-Z51-AA51-AB51-AC51-AD51-AE51-AF51 -> 2805.844 | AH51: =IF(ISNUMBER(MATCH(A51,'畅想出运数据（核算明细导出）'!$C$2:$C$484,0)),"有","无") -> 有
A52: Y25D0903 | B52: 46047 | C52: 美国0830 | D52: 品牌商 | E52: 昊特赛十公司 | F52: 办公室 | H52: 市场八十司 | I52: 业务办公室 | J52: 功能照明 | K52: 头灯及野营灯 | L52: 头灯 | N52: F-YNT-头灯 | O52: 郭红勇 | P52: 外部引进 | Q52: USD | R52: 6.95 | S52: 8709.12 | T52: 8709.12 | U52: 60.96 | V52: 50 | W52: 0 | X52: 63110.88 | Y52: 7260.54 | Z52: 2607 | AA52: 0 | AB52: 0 | AC52: 0 | AD52: 0 | AE52: 0 | AF52: 0 | AG52: =(T52-U52-V52-W52)*R52-X52+Y52-Z52-AA52-AB52-AC52-AD52-AE52-AF52 -> 1299.872 | AH52: =IF(ISNUMBER(MATCH(A52,'畅想出运数据（核算明细导出）'!$C$2:$C$484,0)),"有","无") -> 有
A53: HSA25D010-2 | B53: 46078 | C53: 波兰749 | D53: 渠道商 | E53: 昊特赛一公司 | F53: 客户第一组 | H53: 市场七一司 | I53: 客户第二组 | J53: 工艺陶瓷 | K53: 陶瓷工艺品 | L53: 常规陶瓷工艺品 | N53: GD-PC200-1024 | O53: 钟 琪 | P53: 外部引进 | Q53: USD | R53: 6.9 | S53: 957.6 | T53: 957.6 | U53: 6.7 | V53: 50 | W53: 0 | X53: 4636.8 | Y53: 369.3 | Z53: 1400.34 | AA53: 0 | AB53: 0 | AC53: 0 | AD53: 0 | AE53: 0 | AF53: 0 | AG53: =(T53-U53-V53-W53)*R53-X53+Y53-Z53-AA53-AB53-AC53-AD53-AE53-AF53 -> 548.37 | AH53: =IF(ISNUMBER(MATCH(A53,'畅想出运数据（核算明细导出）'!$C$2:$C$484,0)),"有","无") -> 有
A54: HSA25D005-1 | B54: 46078 | C54: 波兰749 | D54: 渠道商 | E54: 昊特赛一公司 | F54: 客户第一组 | H54: 市场七一司 | I54: 客户第二组 | J54: 家居装饰品 | K54: 人造绿植 | L54: 常规人造绿植 | N54: GD-HD200-1006 | O54: 钟 琪 | P54: 外部引进 | Q54: USD | R54: 6.92 | S54: 1689.6 | T54: 1689.6 | U54: 11.83 | V54: 50 | W54: 0 | X54: 10936.32 | Y54: 1258.16 | Z54: 281.77 | AA54: 0 | AB54: 0 | AC54: 0 | AD54: 0 | AE54: 0 | AF54: 0 | AG54: =(T54-U54-V54-W54)*R54-X54+Y54-Z54-AA54-AB54-AC54-AD54-AE54-AF54 -> 1304.2384 | AH54: =IF(ISNUMBER(MATCH(A54,'畅想出运数据（核算明细导出）'!$C$2:$C$484,0)),"有","无") -> 有
A55: HSA25J009-1 | B55: 46078 | C55: 波兰749 | D55: 渠道商 | E55: 昊特赛一公司 | F55: 客户第一组 | H55: 市场七一司 | I55: 客户第二组 | J55: 工艺陶瓷 | K55: 陶瓷工艺品 | L55: 常规陶瓷工艺品 | N55: GD-PC200-1026 | O55: 钟 琪 | P55: 外部引进 | Q55: USD | R55: 6.92 | S55: 1229.76 | T55: 1229.76 | U55: 8.61 | V55: 50 | W55: 0 | X55: 8064 | Y55: 642.27 | Z55: 1587.22 | AA55: 0 | AB55: 0 | AC55: 0 | AD55: 0 | AE55: 0 | AF55: 0 | AG55: =(T55-U55-V55-W55)*R55-X55+Y55-Z55-AA55-AB55-AC55-AD55-AE55-AF55 -> -904.592 | AH55: =IF(ISNUMBER(MATCH(A55,'畅想出运数据（核算明细导出）'!$C$2:$C$484,0)),"有","无") -> 有
A56: HSA25D003-11 | B56: 46078 | C56: 波兰749 | D56: 渠道商 | E56: 昊特赛一公司 | F56: 客户第一组 | H56: 市场七一司 | I56: 客户第二组 | J56: 家居装饰品 | K56: 人造绿植 | L56: 常规人造绿植 | N56: GD-HD200-1005 | O56: 钟 琪 | P56: 外部引进 | Q56: USD | R56: 6.9 | S56: 726 | T56: 726 | U56: 5.09 | V56: 42.31 | W56: 0 | X56: 4443.12 | Y56: 511.16 | Z56: 0 | AA56: 0 | AB56: 0 | AC56: 0 | AD56: 0 | AE56: 0 | AF56: 0 | AG56: =(T56-U56-V56-W56)*R56-X56+Y56-Z56-AA56-AB56-AC56-AD56-AE56-AF56 -> 750.38 | AH56: =IF(ISNUMBER(MATCH(A56,'畅想出运数据（核算明细导出）'!$C$2:$C$484,0)),"有","无") -> 有
A57: HSA25D003-11 | B57: 46078 | C57: 波兰749 | D57: 渠道商 | E57: 昊特赛一公司 | F57: 客户第一组 | H57: 市场七一司 | I57: 客户第二组 | J57: 家居装饰品 | K57: 人造绿植 | L57: 常规人造绿植 | N57: GD-HD200-1005 | O57: 钟 琪 | P57: 外部引进 | Q57: USD | R57: 6.9 | S57: 132 | T57: 132 | U57: 0.92 | V57: 7.69 | W57: 0 | X57: 807.84 | Y57: 92.94 | Z57: 0 | AA57: 0 | AB57: 0 | AC57: 0 | AD57: 0 | AE57: 0 | AF57: 0 | AG57: =(T57-U57-V57-W57)*R57-X57+Y57-Z57-AA57-AB57-AC57-AD57-AE57-AF57 -> 136.491 | AH57: =IF(ISNUMBER(MATCH(A57,'畅想出运数据（核算明细导出）'!$C$2:$C$484,0)),"有","无") -> 有
A58: HSA25D003-4 | B58: 46078 | C58: 波兰749 | D58: 渠道商 | E58: 昊特赛一公司 | F58: 客户第一组 | H58: 市场七一司 | I58: 客户第二组 | J58: 厨房收纳 | K58: 厨房置物架 | L58: 纸巾架 | N58: KW-KS600-1001 | O58: 钟 琪 | P58: 外部引进 | Q58: USD | R58: 6.92 | S58: 628.32 | T58: 628.32 | U58: 4.4 | V58: 17.83 | W58: 0 | X58: 4161.6 | Y58: 478.77 | Z58: 0 | AA58: 0 | AB58: 0 | AC58: 0 | AD58: 0 | AE58: 0 | AF58: 0 | AG58: =(T58-U58-V58-W58)*R58-X58+Y58-Z58-AA58-AB58-AC58-AD58-AE58-AF58 -> 511.3128 | AH58: =IF(ISNUMBER(MATCH(A58,'畅想出运数据（核算明细导出）'!$C$2:$C$484,0)),"有","无") -> 有
...

Sheet 畅想出运数据透视
A3: 外销合同 | B3: 求和项:FOB | C3: 求和项:出厂价_预计毛利 | D3: 毛利率
A4: HSA25D001-1 | B4: 649.78 | C4: -604.24 | D4: =TEXT(C4/B4/6.8,"0.00%") -> -13.68%
A5: HSA25D001-2 | B5: 390.46 | C5: -218.2 | D5: =TEXT(C5/B5/6.8,"0.00%") -> -8.22%
A6: HSA25D002-1 | B6: 2072.88 | C6: 579.65 | D6: =TEXT(C6/B6/6.8,"0.00%") -> 4.11%
A7: HSA25D003 | B7: 1772.5 | C7: 1225.91 | D7: =TEXT(C7/B7/6.8,"0.00%") -> 10.17%
A8: HSA25D004 | B8: 1431.95 | C8: 45.3 | D8: =TEXT(C8/B8/6.8,"0.00%") -> 0.47%
A9: HSA25D004-1 | B9: 319.75 | C9: 19.62 | D9: =TEXT(C9/B9/6.8,"0.00%") -> 0.90%
A10: HSA25D005 | B10: 2233.86 | C10: 1745.19 | D10: =TEXT(C10/B10/6.8,"0.00%") -> 11.49%
A11: HSA25D006 | B11: 1846.22 | C11: -284.64 | D11: =TEXT(C11/B11/6.8,"0.00%") -> -2.27%
A12: HSA25D010 | B12: 3887.32 | C12: 1265.43 | D12: =TEXT(C12/B12/6.8,"0.00%") -> 4.79%
A13: HSA25D011 | B13: 123.38 | C13: 131.97 | D13: =TEXT(C13/B13/6.8,"0.00%") -> 15.73%
A14: HSA25J001-1 | B14: 9565.26 | C14: 6741.38 | D14: =TEXT(C14/B14/6.8,"0.00%") -> 10.36%
A15: HSA25J002-1 | B15: 11169.1 | C15: 260.16 | D15: =TEXT(C15/B15/6.8,"0.00%") -> 0.34%
... A146: HSC25X013 | B146: 5894.97 | C146: 2224.72 | D146: =TEXT(C146/B146/6.8,"0.00%") -> 5.55%
A147: 总计 | B147: 2451451.8 | C147: 1070900.1

Sheet 畅想出运数据（核算明细导出）
A1: 业务员 | B1: 部门 | C1: 订单号 | D1: 外销合同 | E1: 客户 | F1: 客户来源 | G1: 签单日 | H1: 出运日 | I1: 出运月份 | J1: 核算月份 | K1: 交货期 | L1: PI交期 | M1: 出货数量 | N1: 一级目录 | O1: 中文品名 | P1: 采购跟单 | Q1: 采购员 | R1: 应收收汇 | S1: 收汇方式 | T1: 海运费+保费 | U1: 出口信保费用 | V1: 其他 | W1: 银行费 | X1: FOB | Y1: 收汇（USD） | Z1: 收汇（RMB） | AA1: 实际FOB | AB1: 内陆费 | AC1: 单证费 | AD1: 其他费 | AE1: 仓储费 | AF1: 验货费 | AG1: 包装设计费 | AH1: 实际FOB(RMB) | AI1: 出厂价_应付货款 | AJ1: 出厂价_退税款 | AK1: 出厂价_资金成本 | AL1: 出厂价_预计毛利 | AM1: 出厂价_毛利率 | AN1: 出厂价_实际毛利（收汇RMB） | AO1: 客户编号 | AP1: 产品编号 | AQ1: 操作月份 | AR1: 出厂价_预计毛利2 | AS1: 组别 | AT1: 二级目录 | AU1: 三级目录 | AV1: 对比畅想结算中心 | AW1: 对比外销合同
A2: 王柯飞 | B2: 昊特赛八公司 | C2: HSA25J001-1 | D2: HSA25J001-1 | E2: LPP | F2: 主动开发 | G2: 2025-08-04 | H2: 2026-02-17 | I2: 2 | J2: 202605 | K2: 197 | L2: 2025-09-20 | M2: 1008 | N2: 其他运动用品 | O2: 弹力带 | P2: 杜 娟 | R2: 594.72 | S2: OA 90 DAYS | T2: 0 | U2: 4.16 | V2: 0 | W2: 7.14 | X2: 533.42 | Y2: 0 | Z2: 0 | AA2: -11.3 | AB2: 0 | AC2: 0 | AD2: 0 | AE2: 0 | AF2: 0 | AG2: 0 | AH2: -77.91 | AI2: 3729.6 | AJ2: 429.07 | AK2: 18.65 | AL2: 358.59 | AM2: 0.0975 | AN2: -3347.86 | AO2: 波兰749 | AP2: PO-OSP2001-001 | AQ2: 202602 | AR2: 426.468 | AS2: 办公室 | AT2: 伸展训练 | AU2: 弹力带 | AV2: =IF(ISNUMBER(MATCH(C2,畅想结算中心!$A$2:$A$436,0)),"有","无") -> 有
A3: 王柯飞 | B3: 昊特赛八公司 | C3: HSA25J001-3 | D3: HSA25J001-1 | E3: LPP | F3: 主动开发 | G3: 2025-08-04 | H3: 2026-02-17 | I3: 2 | J3: 202605 | K3: 197 | L3: 2025-09-20 | M3: 1008 | N3: 瑜伽和普拉提 | O3: 常规瑜伽砖 | P3: 杜 娟 | R3: 786.24 | S3: OA 90 DAYS | T3: 0 | U3: 5.5 | V3: 0 | W3: 9.44 | X3: 766.64 | Y3: 0 | Z3: 0 | AA3: -14.94 | AB3: 0 | AC3: 0 | AD3: 0 | AE3: 0 | AF3: 0 | AG3: 0 | AH3: -103.01 | AI3: 5040 | AJ3: 579.82 | AK3: 25.2 | AL3: 800.38 | AM3: 0.1514 | AN3: -4523.32 | AO3: 波兰749 | AP3: PO-YP2001-002 | AQ3: 202602 | AR3: 890.6618 | AS3: 办公室 | AT3: 瑜伽砖 | AU3: 常规瑜伽砖 | AV3: =IF(ISNUMBER(MATCH(C3,畅想结算中心!$A$2:$A$436,0)),"有","无") -> 有
A4: 王柯飞 | B4: 昊特赛八公司 | C4: HSA25J001-3 | D4: HSA25J001-1 | E4: LPP | F4: 主动开发 | G4: 2025-08-04 | H4: 2026-02-17 | I4: 2 | J4: 202605 | K4: 197 | L4: 2025-09-20 | M4: 512 | N4: 瑜伽和普拉提 | O4: 常规瑜伽垫 | P4: 杜 娟 | R4: 716.8 | S4: OA 90 DAYS | T4: 0 | U4: 5.02 | V4: 0 | W4: 8.6 | X4: 698.93 | Y4: 0 | Z4: 0 | AA4: -13.62 | AB4: 0 | AC4: 0 | AD4: 0 | AE4: 0 | AF4: 0 | AG4: 0 | AH4: -93.91 | AI4: 4710.4 | AJ4: 541.9 | AK4: 23.55 | AL4: 626.87 | AM4: 0.1301 | AN4: -4226.64 | AO4: 波兰749 | AP4: PO-YP1001-001 | AQ4: 202602 | AR4: 709.7115 | AS4: 办公室 | AT4: 瑜伽垫 | AU4: 常规瑜伽垫 | AV4: =IF(ISNUMBER(MATCH(C4,畅想结算中心!$A$2:$A$436,0)),"有","无") -> 有
A5: 王柯飞 | B5: 昊特赛八公司 | C5: HSA25J001-3 | D5: HSA25J001-1 | E5: LPP | F5: 主动开发 | G5: 2025-08-04 | H5: 2026-02-17 | I5: 2 | J5: 202605 | K5: 197 | L5: 2025-09-20 | M5: 1010 | N5: 力量训练 | O5: 哑铃 | P5: 杜 娟 | R5: 1939.2 | S5: OA 90 DAYS | T5: 0 | U5: 13.57 | V5: 0 | W5: 23.27 | X5: 1890.86 | Y5: 0 | Z5: 0 | AA5: -36.85 | AB5: 0 | AC5: 0 | AD5: 0 | AE5: 0 | AF5: 0 | AG5: 0 | AH5: -254.07 | AI5: 13938 | AJ5: 1603.49 | AK5: 69.69 | AL5: 632.71 | AM5: 0.0485 | AN5: -12497.8 | AO5: 波兰749 | AP5: PO-ST3001-002 | AQ5: 202602 | AR5: 862.8388 | AS5: 办公室 | AT5: 哑铃及哑铃凳 | AU5: 哑铃 | AV5: =IF(ISNUMBER(MATCH(C5,畅想结算中心!$A$2:$A$436,0)),"有","无") -> 有
A6: 王柯飞 | B6: 昊特赛八公司 | C6: HSA25J001-3 | D6: HSA25J001-1 | E6: LPP | F6: 主动开发 | G6: 2025-08-04 | H6: 2026-02-17 | I6: 2 | J6: 202605 | K6: 197 | L6: 2025-09-20 | M6: 1008 | N6: 力量训练 | O6: 哑铃 | P6: 杜 娟 | R6: 1008 | S6: OA 90 DAYS | T6: 0 | U6: 7.06 | V6: 0 | W6: 12.1 | X6: 982.87 | Y6: 0 | Z6: 0 | AA6: -19.15 | AB6: 0 | AC6: 0 | AD6: 0 | AE6: 0 | AF6: 0 | AG6: 0 | AH6: -132.03 | AI6: 6955.2 | AJ6: 800.16 | AK6: 34.78 | AL6: 586.77 | AM6: 0.0866 | AN6: -6238.47 | AO6: 波兰749 | AP6: PO-ST3001-001 | AQ6: 202602 | AR6: 704.9755 | AS6: 办公室 | AT6: 哑铃及哑铃凳 | AU6: 哑铃 | AV6: =IF(ISNUMBER(MATCH(C6,畅想结算中心!$A$2:$A$436,0)),"有","无") -> 有
A7: 王柯飞 | B7: 昊特赛八公司 | C7: HSA25J001-3 | D7: HSA25J001-1 | E7: LPP | F7: 主动开发 | G7: 2025-08-04 | H7: 2026-02-17 | I7: 2 | J7: 202605 | K7: 197 | L7: 2025-09-20 | M7: 512 | N7: 瑜伽和普拉提 | O7: 常规瑜伽垫 | P7: 杜 娟 | R7: 716.8 | S7: OA 90 DAYS | T7: 0 | U7: 5.02 | V7: 0 | W7: 8.6 | X7: 698.93 | Y7: 0 | Z7: 0 | AA7: -13.62 | AB7: 0 | AC7: 0 | AD7: 0 | AE7: 0 | AF7: 0 | AG7: 0 | AH7: -93.91 | AI7: 4710.4 | AJ7: 541.9 | AK7: 23.55 | AL7: 626.87 | AM7: 0.1301 | AN7: -4226.64 | AO7: 波兰749 | AP7: PO-YP1001-003 | AQ7: 202602 | AR7: 709.7115 | AS7: 办公室 | AT7: 瑜伽垫 | AU7: 常规瑜伽垫 | AV7: =IF(ISNUMBER(MATCH(C7,畅想结算中心!$A$2:$A$436,0)),"有","无") -> 有
A8: 王柯飞 | B8: 昊特赛八公司 | C8: HSA25J001-3 | D8: HSA25J001-1 | E8: LPP | F8: 主动开发 | G8: 2025-08-04 | H8: 2026-02-17 | I8: 2 | J8: 202605 | K8: 197 | L8: 2025-09-20 | M8: 1008 | N8: 瑜伽和普拉提 | O8: 常规瑜伽砖 | P8: 杜 娟 | R8: 786.24 | S8: OA 90 DAYS | T8: 0 | U8: 5.5 | V8: 0 | W8: 9.44 | X8: 766.64 | Y8: 0 | Z8: 0 | AA8: -14.94 | AB8: 0 | AC8: 0 | AD8: 0 | AE8: 0 | AF8: 0 | AG8: 0 | AH8: -103.01 | AI8: 5040 | AJ8: 579.82 | AK8: 25.2 | AL8: 800.38 | AM8: 0.1514 | AN8: -4523.32 | AO8: 波兰749 | AP8: PO-YP2001-001 | AQ8: 202602 | AR8: 890.6618 | AS8: 办公室 | AT8: 瑜伽砖 | AU8: 常规瑜伽砖 | AV8: =IF(ISNUMBER(MATCH(C8,畅想结算中心!$A$2:$A$436,0)),"有","无") -> 有
A9: 王柯飞 | B9: 昊特赛八公司 | C9: HSA25J001-3 | D9: HSA25J001-1 | E9: LPP | F9: 主动开发 | G9: 2025-08-04 | H9: 2026-02-17 | I9: 2 | J9: 202605 | K9: 197 | L9: 2025-09-20 | M9: 512 | N9: 瑜伽和普拉提 | O9: 常规瑜伽垫 | P9: 杜 娟 | R9: 716.8 | S9: OA 90 DAYS | T9: 0 | U9: 5.02 | V9: 0 | W9: 8.6 | X9: 698.93 | Y9: 0 | Z9: 0 | AA9: -13.62 | AB9: 0 | AC9: 0 | AD9: 0 | AE9: 0 | AF9: 0 | AG9: 0 | AH9: -93.91 | AI9: 4710.4 | AJ9: 541.9 | AK9: 23.55 | AL9: 626.87 | AM9: 0.1301 | AN9: -4226.64 | AO9: 波兰749 | AP9: PO-YP1001-002 | AQ9: 202602 | AR9: 709.7115 | AS9: 办公室 | AT9: 瑜伽垫 | AU9: 常规瑜伽垫 | AV9: =IF(ISNUMBER(MATCH(C9,畅想结算中心!$A$2:$A$436,0)),"有","无") -> 有
A10: 王柯飞 | B10: 昊特赛八公司 | C10: HSA25J001-3 | D10: HSA25J013 | E10: LPP | F10: 主动开发 | G10: 2025-12-17 | H10: 2026-02-17 | I10: 2 | J10: 202605 | K10: 62 | L10: 2026-01-06 | M10: 1008 | N10: 装饰照明 | O10: 太阳能灯串 | P10: 杜 娟 | R10: 1764 | S10: OA 90 DAYS | T10: 0 | U10: 12.35 | V10: 0 | W10: 21.17 | X10: 1720.03 | Y10: 0 | Z10: 0 | AA10: -33.52 | AB10: 0 | AC10: 0 | AD10: 0 | AE10: 0 | AF10: 0 | AG10: 0 | AH10: -231.11 | AI10: 11088 | AJ10: 1275.61 | AK10: 110.88 | AL10: 1935.82 | AM10: 0.1632 | AN10: -10008.41 | AO10: 波兰749 | AP10: PO-GS1001-001 | AQ10: 202602 | AR10: 2192.5933 | AS10: 办公室 | AT10: 节日灯 | AU10: 太阳能灯串 | AV10: =IF(ISNUMBER(MATCH(C10,畅想结算中心!$A$2:$A$436,0)),"有","无") -> 有
A11: 王柯飞 | B11: 昊特赛八公司 | C11: HSA25J004-2 | D11: HSA25J004 | E11: LPP | F11: 主动开发 | G11: 2025-10-27 | H11: 2026-02-27 | I11: 3 | J11: 202605 | K11: 123 | L11: 2025-12-26 | M11: 1008 | N11: 餐厨及户外家具 | O11: 庭院吊篮 | P11: 杜 娟 | R11: 3024 | S11: OA 90 DAYS | T11: 0 | U11: 21.17 | V11: 0 | W11: 36.29 | X11: 2927.61 | Y11: 0 | Z11: 0 | AA11: -57.46 | AB11: 757.83 | AC11: 0 | AD11: 0 | AE11: 0 | AF11: 0 | AG11: 0 | AH11: -393.35 | AI11: 18144 | AJ11: 2087.36 | AK11: 90.72 | AL11: 3136.06 | AM11: 0.1565 | AN11: -17050.1 | AO11: 波兰749 | AP11: PO-OF5001-001 | AQ11: 202602 | AR11: 3475.2115 | AS11: 办公室 | AT11: 户外沙发及吊床 | AU11: 庭院吊篮 | AV11: =IF(ISNUMBER(MATCH(C11,畅想结算中心!$A$2:$A$436,0)),"有","无") -> 有
A12: 蔡载君 | B12: 昊特赛八公司 | C12: HSA25J004-2 | D12: HSG26E002 | E12: LPP | F12: 主动开发 | G12: 2026-01-23 | H12: 2026-02-27 | I12: 3 | J12: 202605 | K12: 35 | L12: 2026-02-23 | M12: 1000 | N12: 商务礼品 | O12: 水晶工艺品 | P12: 蔡载君 | R12: 860 | S12: OA 90 DAYS | T12: 0 | U12: 6.02 | V12: 0 | W12: 10.32 | X12: 832.59 | Y12: 0 | Z12: 0 | AA12: -16.34 | AB12: 8.21 | AC12: 0 | AD12: 0 | AE12: 0 | AF12: 0 | AG12: 0 | AH12: -111.86 | AI12: 6103 | AJ12: 486.08 | AK12: 122.06 | AL12: -47.62 | AM12: -0.0084 | AN12: -5788.41 | AO12: 波兰749 | AP12: CR037 | AQ12: 202602 | AR12: 145.0894 | AS12: 办公室 | AT12: 工艺品 | AU12: 水晶工艺品 | AV12: =IF(ISNUMBER(MATCH(C12,畅想结算中心!$A$2:$A$436,0)),"有","无") -> 有
A13: 王柯飞 | B13: 昊特赛八公司 | C13: HSA25J004-3 | D13: HSA25J001-1 | E13: LPP | F13: 主动开发 | G13: 2025-08-04 | H13: 2026-03-07 | I13: 3 | J13: 202606 | K13: 215 | L13: 2025-09-20 | M13: 1050 | N13: 其他运动用品 | O13: 弹力带 | P13: 杜 娟 | R13: 892.5 | S13: OA 90 DAYS | T13: 0 | U13: 6.25 | V13: 0 | W13: 10.71 | X13: 869.77 | Y13: 0 | Z13: 0 | AA13: -16.96 | AB13: 45.58 | AC13: 0 | AD13: 0 | AE13: 0 | AF13: 0 | AG13: 0 | AH13: -116.92 | AI13: 5880 | AJ13: 676.46 | AK13: 29.4 | AL13: 717.68 | AM13: 0.1197 | AN13: -5321.58 | AO13: 波兰749 | AP13: PO-OSP2001-002 | AQ13: 202603 | AR13: 820.9137 | AS13: 办公室 | AT13: 伸展训练 | AU13: 弹力带 | AV13: =IF(ISNUMBER(MATCH(C13,畅想结算中心!$A$2:$A$436,0)),"有","无") -> 有
... A55: 蔡载君 | B55: 昊特赛八公司 | C55: HSG26E004-2 | D55: HSG26E004 | E55: LPP | F55: 主动开发 | G55: 2026-03-26 | H55: 2026-05-23 | I55: 5 | J55: 202606 | K55: 58 | L55: 2026-11-02 | M55: 800 | N55: 综合运动 | O55: 哑铃 | P55: 陈依萍 | R55: 768 | S55: OA 90 DAYS | T55: 0 | U55: 5.38 | V55: 0 | W55: 9.22 | X55: 742.7 | Y55: 0 | Z55: 0 | AA55: -14.59 | AB55: 120.89 | AC55: 0 | AD55: 0 | AE55: 0 | AF55: 0 | AG55: 0 | AH55: -99.04 | AI55: 5040 | AJ55: 579.82 | AK55: 100.8 | AL55: 359.73 | AM55: 0.0714 | AN55: -4718.37 | AO55: 波兰749 | AP55: PO-ST3001-001 | AQ55: 202605 | AR55: 523.1158 | AS55: 办公室 | AT55: 无氧器械 | AU55: 哑铃 | AV55: =IF(ISNUMBER(MATCH(C55,畅想结算中心!$A$2:$A$436,0)),"有","无") -> 有
A56: 蔡载君 | B56: 昊特赛八公司 | C56: HSG26E004-3 | D56: HSG26E004 | E56: LPP | F56: 主动开发 | G56: 2026-03-26 | H56: 2026-05-28 | I56: 6 | K56: 63 | L56: 2026-11-02 | M56: 1200 | N56: 综合运动 | O56: 哑铃 | P56: 陈依萍 | R56: 1152 | S56: OA 90 DAYS | T56: 0 | U56: 8.06 | V56: 0 | W56: 13.82 | X56: 1115.61 | Y56: 0 | Z56: 0 | AA56: -21.89 | AB56: 131.77 | AC56: 0 | AD56: 0 | AE56: 0 | AF56: 0 | AG56: 0 | AH56: -148.19 | AI56: 7560 | AJ56: 869.73 | AK56: 151.2 | AL56: 579.34 | AM56: 0.0767 | AN56: -7027.82 | AO56: 波兰749 | AP56: PO-ST3001-001 | AQ56: 202605 | AR56: 824.1647 | AS56: 客户第一组 | AT56: 无氧器械 | AU56: 哑铃 | AV56: =IF(ISNUMBER(MATCH(C56,畅想结算中心!$A$2:$A$436,0)),"有","无") -> 有
A57: 蔡载君 | B57: 昊特赛八公司 | C57: HSG26E004-3 | D57: HSG26E004 | E57: LPP | F57: 主动开发 | G57: 2026-03-26 | H57: 2026-05-28 | I57: 6 | K57: 63 | L57: 2026-11-02 | M57: 1500 | N57: 综合运动 | O57: 哑铃 | P57: 陈依萍 | R57: 2820 | S57: OA 90 DAYS | T57: 0 | U57: 19.74 | V57: 0 | W57: 33.84 | X57: 2730.93 | Y57: 0 | Z57: 0 | AA57: -53.57 | AB57: 329.41 | AC57: 0 | AD57: 0 | AE57: 0 | AF57: 0 | AG57: 0 | AH57: -362.66 | AI57: 18900 | AJ57: 2174.34 | AK57: 378 | AL57: 1055.05 | AM57: 0.0571 | AN57: -17566.7 | AO57: 波兰749 | AP57: PO-ST3001-002 | AQ57: 202605 | AR57: 1662.0707 | AS57: 客户第一组 | AT57: 无氧器械 | AU57: 哑铃 | AV57: =IF(ISNUMBER(MATCH(C57,畅想结算中心!$A$2:$A$436,0)),"有","无") -> 有
A58: 蔡载君 | B58: 昊特赛八公司 | C58: HSG26E004-4 | D58: HSG26E003 | E58: LPP | F58: 主动开发 | G58: 2026-03-25 | H58: 2026-05-28 | I58: 6 | K58: 64 | L58: 2026-09-28 | M58: 1200 | N58: 瑜伽和普拉提 | O58: 瑜伽负重袋 | P58: 陈依萍 | R58: 2076 | S58: OA 90 DAYS | T58: 0 | U58: 14.53 | V58: 0 | W58: 24.91 | X58: 2021.55 | Y58: 0 | Z58: 0 | AA58: -39.45 | AB58: 273.16 | AC58: 0 | AD58: 0 | AE58: 0 | AF58: 0 | AG58: 0 | AH58: -267.07 | AI58: 12720 | AJ58: 1463.36 | AK58: 63.6 | AL58: 2092.29 | AM58: 0.1529 | AN58: -11691.78 | AO58: 波兰749 | AP58: PO-YP6001-002 | AQ58: 202605 | AR58: 2324.5306 | AS58: 客户第一组 | AT58: 其他瑜伽和普拉提用品 | AU58: 瑜伽负重袋 | AV58: =IF(ISNUMBER(MATCH(C58,畅想结算中心!$A$2:$A$436,0)),"有","无") -> 有
A59: 蔡载君 | B59: 昊特赛八公司 | C59: HSG26E004-4 | D59: HSG26E004 | E59: LPP | F59: 主动开发 | G59: 2026-03-26 | H59: 2026-05-28 | I59: 6 | K59: 63 | L59: 2026-11-02 | M59: 1008 | N59: 瑜伽平衡 | O59: 常规瑜伽砖 | P59: 陈依萍 | R59: 735.84 | S59: OA 90 DAYS | T59: 0 | U59: 5.15 | V59: 0 | W59: 8.83 | X59: 716.54 | Y59: 0 | Z59: 0 | AA59: -13.98 | AB59: 281.9 | AC59: 0 | AD59: 0 | AE59: 0 | AF59: 0 | AG59: 0 | AH59: -94.64 | AI59: 4636.8 | AJ59: 533.44 | AK59: 23.18 | AL59: 442.46 | AM59: 0.0912 | AN59: -4443.32 | AO59: 波兰749 | AP59: PO-YP2001-001 | AQ59: 202605 | AR59: 525.4166 | AS59: 客户第一组 | AT59: 训练器材 | AU59: 常规瑜伽砖 | AV59: =IF(ISNUMBER(MATCH(C59,畅想结算中心!$A$2:$A$436,0)),"有","无") -> 有
A60: 蔡载君 | B60: 昊特赛八公司 | C60: HSG26E004-4 | D60: HSG26E004 | E60: LPP | F60: 主动开发 | G60: 2026-03-26 | H60: 2026-05-28 | I60: 6 | K60: 63 | L60: 2026-11-02 | M60: 1504 | N60: 瑜伽平衡 | O60: 常规瑜伽垫 | P60: 陈依萍 | R60: 2015.36 | S60: OA 90 DAYS | T60: 0 | U60: 14.11 | V60: 0 | W60: 24.19 | X60: 1962.5 | Y60: 0 | Z60: 0 | AA60: -38.29 | AB60: 932.94 | AC60: 0 | AD60: 0 | AE60: 0 | AF60: 0 | AG60: 0 | AH60: -259.22 | AI60: 13836.8 | AJ60: 1591.84 | AK60: 69.18 | AL60: 38.85 | AM60: 0.0029 | AN60: -13342.58 | AO60: 波兰749 | AP60: PO-YP1001-001 | AQ60: 202605 | AR60: 271.7303 | AS60: 客户第一组 | AT60: 训练器材 | AU60: 常规瑜伽垫 | AV60: =IF(ISNUMBER(MATCH(C60,畅想结算中心!$A$2:$A$436,0)),"有","无") -> 有
A61: 蔡载君 | B61: 昊特赛八公司 | C61: HSG26E004-4 | D61: HSG26E004 | E61: LPP | F61: 主动开发 | G61: 2026-03-26 | H61: 2026-05-28 | I61: 6 | K61: 63 | L61: 2026-11-02 | M61: 810 | N61: 瑜伽平衡 | O61: 常规平衡垫 | P61: 陈依萍 | R61: 1449.9 | S61: OA 90 DAYS | T61: 0 | U61: 10.15 | V61: 0 | W61: 17.4 | X61: 1411.87 | Y61: 0 | Z61: 0 | AA61: -27.55 | AB61: 476.94 | AC61: 0 | AD61: 0 | AE61: 0 | AF61: 0 | AG61: 0 | AH61: -186.51 | AI61: 9963 | AJ61: 1146.19 | AK61: 49.81 | AL61: 214.65 | AM61: 0.0225 | AN61: -9412.28 | AO61: 波兰749 | AP61: PO-BT3001-001 | AQ61: 202605 | AR61: 382.2602 | AS61: 客户第一组 | AT61: 训练器材 | AU61: 常规瑜伽垫 | AV61: =IF(ISNUMBER(MATCH(C61,畅想结算中心!$A$2:$A$436,0)),"有","无") -> 有
A62: 蔡载君 | B62: 昊特赛八公司 | C62: HSG26E004-4 | D62: HSG26E004 | E62: LPP | F62: 主动开发 | G62: 2026-03-26 | H62: 2026-05-28 | I62: 6 | K62: 63 | L62: 2026-11-02 | M62: 800 | N62: 综合运动 | O62: 弹力带 | P62: 陈依萍 | R62: 640 | S62: OA 90 DAYS | T62: 0 | U62: 4.48 | V62: 0 | W62: 7.68 | X62: 623.21 | Y62: 0 | Z62: 0 | AA62: -12.16 | AB62: 35.06 | AC62: 0 | AD62: 0 | AE62: 0 | AF62: 0 | AG62: 0 | AH62: -82.32 | AI62: 4000 | AJ62: 460.18 | AK62: 20 | AL62: 624.19 | AM62: 0.1479 | AN62: -3625.21 | AO62: 波兰749 | AP62: PO-OSP2001-002 | AQ62: 202605 | AR62: 696.1834 | AS62: 客户第一组 | AT62: 其他体育用品 | AU62: 弹力带 | AV62: =IF(ISNUMBER(MATCH(C62,畅想结算中心!$A$2:$A$436,0)),"有","无") -> 有
A63: 李欣然 | B63: 昊特赛二公司 | C63: HSB25E023-1 | D63: HSB25E023 | E63: RMS | F63: 主动开发 | G63: 2025-10-15 | H63: 2026-01-13 | I63: 1 | J63: 202605 | K63: 90 | L63: 2025-11-15 | M63: 3900 | N63: 手工艺品及DIY玩具 | O63: 其他常规DIY玩具 | P63: 叶柳涵 | R63: 3120 | S63: OA 60DAYS | T63: 0 | U63: 21.84 | V63: 0 | W63: 18.72 | X63: 3029.44 | Y63: 0 | Z63: 0 | AA63: -40.56 | AB63: 0 | AC63: 0 | AD63: 0 | AE63: 0 | AF63: 0 | AG63: 0 | AH63: -282.44 | AI63: 19968 | AJ63: 2297.2 | AK63: 399.36 | AL63: 3025.65 | AM63: 0.1434 | AN63: -18222.24 | AO63: 英国2962 | AP63: OD273-CN001 | AQ63: 202601 | AR63: 3555.3705 | AS63: 客户第一组 | AT63: 创意类及材料包 | AU63: 其他常规DIY玩具 | AV63: =IF(ISNUMBER(MATCH(C63,畅想结算中心!$A$2:$A$436,0)),"有","无") -> 有
A64: 李欣然 | B64: 昊特赛二公司 | C64: HSB25E023-2 | D64: HSB25E023 | E64: RMS | F64: 主动开发 | G64: 2025-10-15 | H64: 2026-01-13 | I64: 1 | K64: 90 | L64: 2025-11-15 | M64: 6762 | N64: 手工艺品及DIY玩具 | O64: 其他常规DIY玩具 | P64: 叶柳涵 | R64: 5409.6 | S64: OA 60DAYS | T64: 0 | U64: 37.87 | V64: 108.19 | W64: 32.46 | X64: 5181.08 | Y64: 0 | Z64: 0 | AA64: -178.52 | AB64: 0 | AC64: 0 | AD64: 0 | AE64: 0 | AF64: 0 | AG64: 0 | AH64: -1243.14 | AI64: 34621.44 | AJ64: 3983 | AK64: 692.43 | AL64: 4748.1 | AM64: 0.1316 | AN64: -32347.98 | AO64: 英国2962 | AP64: OD273-CN001 | AQ64: 202601 | AR64: 5666.5646 | AS64: 客户第一组 | AT64: 创意类及材料包 | AU64: 其他常规DIY玩具 | AV64: =IF(ISNUMBER(MATCH(C64,畅想结算中心!$A$2:$A$436,0)),"有","无") -> 有
A65: 李欣然 | B65: 昊特赛二公司 | C65: HSB25E023-3 | D65: HSB25E023 | E65: RMS | F65: 主动开发 | G65: 2025-10-15 | H65: 2026-01-13 | I65: 1 | J65: 202605 | K65: 90 | L65: 2025-11-15 | M65: 4482 | N65: 手工艺品及DIY玩具 | O65: 其他常规DIY玩具 | P65: 叶柳涵 | R65: 3585.6 | S65: OA 60DAYS | T65: 0 | U65: 25.1 | V65: 0 | W65: 21.51 | X65: 3488.99 | Y65: 0 | Z65: 0 | AA65: -46.61 | AB65: 0 | AC65: 0 | AD65: 0 | AE65: 0 | AF65: 0 | AG65: 0 | AH65: -324.57 | AI65: 22947.84 | AJ65: 2640.02 | AK65: 458.96 | AL65: 3529.15 | AM65: 0.1453 | AN65: -20941.57 | AO65: 英国2962 | AP65: OD273-CN001 | AQ65: 202601 | AR65: 4137.8948 | AS65: 客户第一组 | AT65: 创意类及材料包 | AU65: 其他常规DIY玩具 | AV65: =IF(ISNUMBER(MATCH(C65,畅想结算中心!$A$2:$A$436,0)),"有","无") -> 有
A66: 李欣然 | B66: 昊特赛二公司 | C66: HSB25E023-4 | D66: HSB25E023 | E66: RMS | F66: 主动开发 | G66: 2025-10-15 | H66: 2026-01-13 | I66: 1 | J66: 202605 | K66: 90 | L66: 2025-11-15 | M66: 5448 | N66: 手工艺品及DIY玩具 | O66: 其他常规DIY玩具 | P66: 叶柳涵 | R66: 4358.4 | S66: OA 60DAYS | T66: 0 | U66: 30.51 | V66: 87.17 | W66: 26.15 | X66: 4164.57 | Y66: 0 | Z66: 0 | AA66: -143.83 | AB66: 0 | AC66: 0 | AD66: 0 | AE66: 0 | AF66: 0 | AG66: 0 | AH66: -1001.57 | AI66: 27893.76 | AJ66: 3209.02 | AK66: 557.88 | AL66: 3757.78 | AM66: 0.1296 | AN66: -26062.09 | AO66: 英国2962 | AP66: OD273-CN001 | AQ66: 202601 | AR66: 4497.7544 | AS66: 客户第一组 | AT66: 创意类及材料包 | AU66: 其他常规DIY玩具 | AV66: =IF(ISNUMBER(MATCH(C66,畅想结算中心!$A$2:$A$436,0)),"有","无") -> 有
A67: 李欣然 | B67: 昊特赛二公司 | C67: HSB25E023-5 | D67: HSB25E023 | E67: RMS | F67: 主动开发 | G67: 2025-10-15 | H67: 2026-01-13 | I67: 1 | J67: 202605 | K67: 90 | L67: 2025-11-15 | M67: 4182 | N67: 手工艺品及DIY玩具 | O67: 其他常规DIY玩具 | P67: 叶柳涵 | R67: 3345.6 | S67: OA 60DAYS | T67: 0 | U67: 23.42 | V67: 0 | W67: 20.07 | X67: 3252.11 | Y67: 0 | Z67: 0 | AA67: -43.49 | AB67: 0 | AC67: 0 | AD67: 0 | AE67: 0 | AF67: 0 | AG67: 0 | AH67: -302.85 | AI67: 21411.84 | AJ67: 2463.31 | AK67: 428.24 | AL67: 3269.62 | AM67: 0.1444 | AN67: -19539.86 | AO67: 英国2962 | AP67: OD273-CN001 | AQ67: 202601 | AR67: 3837.6216 | AS67: 客户第一组 | AT67: 创意类及材料包 | AU67: 其他常规DIY玩具 | AV67: =IF(ISNUMBER(MATCH(C67,畅想结算中心!$A$2:$A$436,0)),"有","无") -> 有
A68: 李欣然 | B68: 昊特赛二公司 | C68: HSB25E023-6 | D68: HSB25E023 | E68: RMS | F68: 主动开发 | G68: 2025-10-15 | H68: 2026-01-13 | I68: 1 | J68: 202605 | K68: 90 | L68: 2025-11-15 | M68: 5226 | N68: 手工艺品及DIY玩具 | O68: 其他常规DIY玩具 | P68: 叶柳涵 | R68: 4180.8 | S68: OA 60DAYS | T68: 0 | U68: 29.27 | V68: 0 | W68: 25.08 | X68: 4076.45 | Y68: 0 | Z68: 0 | AA68: -54.35 | AB68: 0 | AC68: 0 | AD68: 0 | AE68: 0 | AF68: 0 | AG68: 0 | AH68: -378.47 | AI68: 26757.12 | AJ68: 3078.25 | AK68: 535.14 | AL68: 4172.76 | AM68: 0.147 | AN68: -24417.83 | AO68: 英国2962 | AP68: OD273-CN001 | AQ68: 202601 | AR68: 4882.547 | AS68: 客户第一组 | AT68: 创意类及材料包 | AU68: 其他常规DIY玩具 | AV68: =IF(ISNUMBER(MATCH(C68,畅想结算中心!$A$2:$A$436,0)),"有","无") -> 有
A69: 李雅婷 | B69: 昊特赛二公司 | C69: HSB25M024-1 | D69: HSB25M024 | E69: RMS | F69: 主动开发 | G69: 2025-10-21 | H69: 2026-01-22 | I69: 1 | J69: 202605 | K69: 93 | L69: 2025-12-09 | M69: 333 | N69: 经典玩具 | O69: 常规发光玩具 | P69: 叶柳涵 | R69: 606.06 | S69: OA 60DAYS | T69: 0 | U69: 4.24 | V69: 0 | W69: 3.64 | X69: 548.18 | Y69: 0 | Z69: 0 | AA69: -7.88 | AB69: 1300 | AC69: 0 | AD69: 0 | AE69: 0 | AF69: 0 | AG69: 0 | AH69: -54.77 | AI69: 4195.8 | AJ69: 482.7 | AK69: 83.92 | AL69: -1286.73 | AM69: -0.3377 | AN69: -5126.49 | AO69: 英国2962 | AP69: LT035-led-1 | AQ69: 202601 | AR69: -1177.5068 | AS69: 办公室 | AT69: 发光玩具 | AU69: 常规发光玩具 | AV69: =IF(ISNUMBER(MATCH(C69,畅想结算中心!$A$2:$A$436,0)),"有","无") -> 有
A70: 李雅婷 | B70: 昊特赛二公司 | C70: HSB25M024-10 | D70: HSB25M024 | E70: RMS | F70: 主动开发 | G70: 2025-10-21 | H70: 2026-01-15 | I70: 1 | J70: 202605 | K70: 86 | L70: 2025-12-09 | M70: 1272 | N70: 运动休闲包 | O70: 常规沙滩包 | P70: 叶柳涵 | R70: 4833.6 | S70: OA 60DAYS | T70: 0 | U70: 33.84 | V70: 96.67 | W70: 29 | X70: 4627.7 | Y70: 0 | Z70: 0 | AA70: -159.51 | AB70: 2501.46 | AC70: 0 | AD70: 0 | AE70: 0 | AF70: 0 | AG70: 0 | AH70: -1109.74 | AI70: 31800 | AJ70: 3658.41 | AK70: 636 | AL70: 916.78 | AM70: 0.0285 | AN70: -32187.02 | AO70: 英国2962 | AP70: BB001-STB-1 | AQ70: 202601 | AR70: 1754.5429 | AS70: 办公室 | AT70: 沙滩包 | AU70: 常规沙滩包 | AV70: =IF(ISNUMBER(MATCH(C70,畅想结算中心!$A$2:$A$436,0)),"有","无") -> 有
A71: 李雅婷 | B71: 昊特赛二公司 | C71: HSB25M024-10 | D71: HSB25M024 | E71: RMS | F71: 主动开发 | G71: 2025-10-21 | H71: 2026-01-15 | I71: 1 | J71: 202605 | K71: 86 | L71: 2025-12-09 | M71: 2352 | N71: 装扮玩具 | O71: 其他常规装扮玩具 | P71: 叶柳涵 | R71: 376.32 | S71: OA 60DAYS | T71: 0 | U71: 2.63 | V71: 7.53 | W71: 2.26 | X71: 360.29 | Y71: 0 | Z71: 0 | AA71: -12.42 | AB71: 98.54 | AC71: 0 | AD71: 0 | AE71: 0 | AF71: 0 | AG71: 0 | AH71: -86.41 | AI71: 2916.48 | AJ71: 335.52 | AK71: 58.33 | AL71: -231.22 | AM71: -0.0922 | AN71: -2808.52 | AO71: 英国2962 | AP71: 0D322-PS001 | AQ71: 202601 | AR71: -157.1655 | AS71: 办公室 | AT71: 其他装扮玩具 | AU71: 其他常规装扮玩具 | AV71: =IF(ISNUMBER(MATCH(C71,畅想结算中心!$A$2:$A$436,0)),"有","无") -> 有
A72: 李雅婷 | B72: 昊特赛二公司 | C72: HSB25M024-11 | D72: HSB25M024 | E72: RMS | F72: 主动开发 | G72: 2025-10-21 | H72: 2026-01-17 | I72: 1 | J72: 202605 | K72: 88 | L72: 2025-12-09 | M72: 2400 | N72: 装扮玩具 | O72: 其他常规装扮玩具 | P72: 叶柳涵 | R72: 384 | S72: OA 60DAYS | T72: 0 | U72: 2.69 | V72: 11.52 | W72: 2.3 | X72: 363.7 | Y72: 0 | Z72: 0 | AA72: -16.51 | AB72: 119.48 | AC72: 0 | AD72: 0 | AE72: 0 | AF72: 0 | AG72: 0 | AH72: -114.93 | AI72: 2976 | AJ72: 342.37 | AK72: 59.52 | AL72: -280.81 | AM72: -0.1109 | AN72: -2911.54 | AO72: 英国2962 | AP72: 0D322-PS001 | AQ72: 202601 | AR72: -205.2761 | AS72: 办公室 | AT72: 其他装扮玩具 | AU72: 其他常规装扮玩具 | AV72: =IF(ISNUMBER(MATCH(C72,畅想结算中心!$A$2:$A$436,0)),"有","无") -> 有
A73: 李雅婷 | B73: 昊特赛二公司 | C73: HSB25M024-11 | D73: HSB25M024 | E73: RMS | F73: 主动开发 | G73: 2025-10-21 | H73: 2026-01-17 | I73: 1 | J73: 202605 | K73: 88 | L73: 2025-12-09 | M73: 1232 | N73: 运动休闲包 | O73: 常规沙滩包 | P73: 叶柳涵 | R73: 4681.6 | S73: OA 60DAYS | T73: 0 | U73: 32.77 | V73: 140.45 | W73: 28.09 | X73: 4434.08 | Y73: 0 | Z73: 0 | AA73: -201.31 | AB73: 2880.52 | AC73: 0 | AD73: 0 | AE73: 0 | AF73: 0 | AG73: 0 | AH73: -1401.38 | AI73: 30800 | AJ73: 3543.36 | AK73: 616 | AL73: 113.81 | AM73: 0.0037 | AN73: -31959 | AO73: 英国2962 | AP73: BB001-STB-1 | AQ73: 202601 | AR73: 925.3504 | AS73: 办公室 | AT73: 沙滩包 | AU73: 常规沙滩包 | AV73: =IF(ISNUMBER(MATCH(C73,畅想结算中心!$A$2:$A$436,0)),"有","无") -> 有
A74: 李雅婷 | B74: 昊特赛二公司 | C74: HSB25M024-2 | D74: HSB25M024 | E74: RMS | F74: 主动开发 | G74: 2025-10-21 | H74: 2026-01-14 | I74: 1 | J74: 202605 | K74: 85 | L74: 2025-12-09 | M74: 2020 | N74: 装扮玩具 | O74: 常规工具玩具 | P74: 叶柳涵 | R74: 1616 | S74: OA 60DAYS | T74: 0 | U74: 11.31 | V74: 0 | W74: 9.7 | X74: 1585.57 | Y74: 0 | Z74: 0 | AA74: -21.01 | AB74: 1090.17 | AC74: 0 | AD74: 0 | AE74: 0 | AF74: 0 | AG74: 0 | AH74: -146.36 | AI74: 9898 | AJ74: 1138.71 | AK74: 197.96 | AL74: 997.81 | AM74: 0.0903 | AN74: -10126.23 | AO74: 英国2962 | AP74: TT003-FJWJ001 | AQ74: 202601 | AR74: 1263.3453 | AS74: 办公室 | AT74: 工具玩具 | AU74: 常规工具玩具 | AV74: =IF(ISNUMBER(MATCH(C74,畅想结算中心!$A$2:$A$436,0)),"有","无") -> 有
A75: 李雅婷 | B75: 昊特赛二公司 | C75: HSB25M024-2 | D75: HSB25M024 | E75: RMS | F75: 主动开发 | G75: 2025-10-21 | H75: 2026-01-14 | I75: 1 | J75: 202605 | K75: 85 | L75: 2025-12-09 | M75: 888 | N75: 游泳装备 | O75: 游泳圈 | P75: 叶柳涵 | R75: 1864.8 | S75: OA 60DAYS | T75: 0 | U75: 13.05 | V75: 0 | W75: 11.19 | X75: 1829.69 | Y75: 0 | Z75: 0 | AA75: -24.24 | AB75: 277.62 | AC75: 0 | AD75: 0 | AE75: 0 | AF75: 0 | AG75: 0 | AH75: -168.86 | AI75: 10656 | AJ75: 1225.91 | AK75: 213.12 | AL75: 2824.98 | AM75: 0.2216 | AN75: -10011.76 | AO75: 英国2962 | AP75: ST047-YQ-1 | AQ75: 202601 | AR75: 3115.98 | AS75: 办公室 | AT75: 游泳训练器材 | AU75: 游泳圈 | AV75: =IF(ISNUMBER(MATCH(C75,畅想结算中心!$A$2:$A$436,0)),"有","无") -> 有
A76: 李雅婷 | B76: 昊特赛二公司 | C76: HSB25M024-2 | D76: HSB25M024 | E76: RMS | F76: 主动开发 | G76: 2025-10-21 | H76: 2026-01-14 | I76: 1 | J76: 202605 | K76: 85 | L76: 2025-12-09 | M76: 444 | N76: 游泳装备 | O76: 游泳圈 | P76: 叶柳涵 | R76: 2264.4 | S76: OA 60DAYS | T76: 0 | U76: 15.85 | V76: 0 | W76: 13.59 | X76: 2221.76 | Y76: 0 | Z76: 0 | AA76: -29.44 | AB76: 330.04 | AC76: 0 | AD76: 0 | AE76: 0 | AF76: 0 | AG76: 0 | AH76: -205.08 | AI76: 12432 | AJ76: 1430.23 | AK76: 248.64 | AL76: 3896.55 | AM76: 0.2518 | AN76: -11690.87 | AO76: 英国2962 | AP76: ST049-YQ-2 | AQ76: 202601 | AR76: 4239.86 | AS76: 办公室 | AT76: 游泳训练器材 | AU76: 游泳圈 | AV76: =IF(ISNUMBER(MATCH(C76,畅想结算中心!$A$2:$A$436,0)),"有","无") -> 有
... A99: 窦宇佳 | B99: 昊特赛九公司 | C99: HSA25Y001-4 | D99: HSA25Y007 | E99: LPP | F99: 主动开发 | G99: 2025-10-29 | H99: 2026-01-29 | I99: 2 | J99: 202605 | K99: 92 | L99: 2026-03-27 | M99: 1008 | N99: DIY玩具 | O99: 其他DIY玩具 | P99: 李雅婷 | R99: 1108.8 | S99: OA 90 DAYS | T99: 0 | U99: 7.76 | V99: 0 | W99: 13.3 | X99: 1058.13 | Y99: 0 | Z99: 0 | AA99: -21.07 | AB99: 769.07 | AC99: 0 | AD99: 0 | AE99: 0 | AF99: 0 | AG99: 0 | AH99: -146.17 | AI99: 7358.4 | AJ99: 846.54 | AK99: 73.58 | AL99: -13.74 | AM99: -0.0019 | AN99: -7408.36 | AO99: 波兰749 | AP99: OC003-MQ-brown | AQ99: 202603 | AR99: 152.1137 | AS99: 客户第一组 | AT99: 其他DIY玩具 | AU99: 其他常规DIY玩具 | AV99: =IF(ISNUMBER(MATCH(C99,畅想结算中心!$A$2:$A$436,0)),"有","无") -> 有
A100: 王 晶 | B100: 昊特赛九公司 | C100: HSA25Y002-4 | D100: HSA25Y002 | E100: LPP | F100: 主动开发 | G100: 2025-12-19 | H100: 2026-02-09 | I100: 2 | K100: 52 | L100: 2026-01-16 | M100: 1008 | N100: 玩偶玩具 | O100: 方面包 | P100: 李雅婷 | R100: 1814.4 | S100: OA 90 DAYS | T100: 0 | U100: 12.7 | V100: 0 | W100: 21.77 | X100: 1729.93 | Y100: 0 | Z100: 0 | AA100: -34.47 | AB100: 1836.76 | AC100: 0 | AD100: 0 | AE100: 0 | AF100: 0 | AG100: 0 | AH100: -238.61 | AI100: 12821.76 | AJ100: 1475.07 | AK100: 128.22 | AL100: -1336.58 | AM100: -0.1116 | AN100: -13399.58 | AO100: 波兰749 | AP100: KB-DL200-122 | AQ100: 202602 | AR100: -1057.6574 | AS100: 客户第一组 | AT100: 布艺玩偶 | AU100: 常规布艺玩偶 | AV100: =IF(ISNUMBER(MATCH(C100,畅想结算中心!$A$2:$A$436,0)),"有","无") -> 有
A101: 王 晶 | B101: 昊特赛九公司 | C101: HSA25Y002-5 | D101: HSA25Y002 | E101: LPP | F101: 主动开发 | G101: 2025-12-19 | H101: 2026-03-10 | I101: 3 | K101: 81 | L101: 2026-01-16 | M101: 996 | N101: 玩偶玩具 | O101: 方面包 | P101: 李雅婷 | R101: 1792.8 | S101: OA 90 DAYS | T101: 0 | U101: 12.55 | V101: 0 | W101: 21.51 | X101: 1708.74 | Y101: 0 | Z101: 0 | AA101: -34.06 | AB101: 1452.14 | AC101: 0 | AD101: 0 | AE101: 0 | AF101: 0 | AG101: 0 | AH101: -234.01 | AI101: 12669.12 | AJ101: 1457.51 | AK101: 126.69 | AL101: -1050.37 | AM101: -0.0895 | AN101: -12876.67 | AO101: 波兰749 | AP101: KB-DL200-122 | AQ101: 202603 | AR101: -775.895 | AS101: 客户第一组 | AT101: 布艺玩偶 | AU101: 常规布艺玩偶 | AV101: =IF(ISNUMBER(MATCH(C101,畅想结算中心!$A$2:$A$436,0)),"有","无") -> 有
A102: 窦宇佳 | B102: 昊特赛九公司 | C102: HSA25Y007-3 | D102: HSA25Y007 | E102: LPP | F102: 主动开发 | G102: 2025-10-29 | H102: 2026-04-02 | I102: 4 | K102: 155 | L102: 2026-03-27 | M102: 984 | N102: DIY玩具 | O102: 其他DIY玩具 | P102: 李雅婷 | R102: 1082.4 | S102: OA 90 DAYS | T102: 0 | U102: 7.58 | V102: 0 | W102: 12.99 | X102: 1011.83 | Y102: 0 | Z102: 0 | AA102: -20.57 | AB102: 2017.28 | AC102: 0 | AD102: 0 | AE102: 0 | AF102: 0 | AG102: 0 | AH102: -141.39 | AI102: 7183.2 | AJ102: 826.39 | AK102: 71.83 | AL102: -1491.01 | AM102: -0.2144 | AN102: -8498.03 | AO102: 波兰749 | AP102: OC003-MQ-brown | AQ102: 202604 | AR102: -1329.8914 | AS102: 办公室 | AT102: 其他DIY玩具 | AU102: 其他常规DIY玩具 | AV102: =IF(ISNUMBER(MATCH(C102,畅想结算中心!$A$2:$A$436,0)),"有","无") -> 有
A103: 窦宇佳 | B103: 昊特赛九公司 | C103: HSA25Y012 | D103: HSA25Y012 | E103: LPP | F103: 主动开发 | G103: 2025-11-18 | H103: 2026-05-05 | I103: 5 | K103: 168 | L103: 2026-03-20 | M103: 1008 | N103: 宠物洗美及出行 | O103: 宠物包 | P103: 任江惠 | R103: 4011.84 | S103: OA 90 DAYS | T103: 0 | U103: 28.08 | V103: 0 | W103: 48.14 | X103: 3885.62 | Y103: 0 | Z103: 0 | AA103: -76.22 | AB103: 1326.3 | AC103: 0 | AD103: 0 | AE103: 0 | AF103: 0 | AG103: 0 | AH103: -520.01 | AI103: 27720 | AJ103: 3189.03 | AK103: 554.4 | AL103: 97.97 | AM103: 0.0037 | AN103: -26603.25 | AO103: 波兰749 | AP103: PO-PN600-102 | AQ103: 202605 | AR103: 980.8041 | AS103: 客户第一组 | AT103: 宠物背带及旅行用品 | AU103: 宠物包 | AV103: =IF(ISNUMBER(MATCH(C103,畅想结算中心!$A$2:$A$436,0)),"有","无") -> 有
...

Sheet 畅想外销合同（外销合同导出）
A1: 分公司 | B1: 外销合同 | C1: 合同日期 | D1: 外 销 员 | E1: 客户简称 | F1: 预算毛利率 | G1: 外销币种 | H1: 已出运金额 | I1: 出运毛利率 | J1: 实际毛利额 | K1: 毛利额差异 | L1: 货值合计 | M1: 人民币货值 | N1: 毛利额 | O1: 首次内部交期 | P1: 外销交期 | Q1: 内部交期 | R1: 交付月份 | S1: 审核通过 | T1: 客户编号 | U1: 我方公司 | V1: 价格条款 | W1: 结汇方式 | X1: 已收定金 | Y1: 跟 单 员 | Z1: 审核状态 | AA1: 数量合计 | AB1: 核算美金合计 | AC1: 箱数合计 | AD1: 毛重合计 | AE1: 净重合计 | AF1: 体积合计 | AG1: 折合美金 | AH1: 货值总计 | AI1: 预计 汇率 | AJ1: 推广费 | AK1: 退 税 款 | AL1: 单证银行费 | AM1: 单证 费用 | AN1: 验货 费用 | AO1: 实收 FOB | AP1: 出口信用保险费 | AQ1: 毛 利 | AR1: 合同备注 | AS1: 情况说明(不会带到采购合同) | AT1: 是否监装 | AU1: 工艺单提供时间 | AV1: 柜型 | AW1: 信保抬头 | AX1: 资金成本 | AY1: 同意特采 | AZ1: 是否客验 | BA1: 组别 | BB1: 拼柜类型 | BC1: 客诉预提 | BD1: 账期利息 | BE1: 需要定金未到 | BF1: 分公司毛利 | BG1: 45天以上 | BH1: 数据来源 | BI1: 出厂总价合计 | BJ1: 流程启动次数 | BK1: 客验时间 | BL1: 定金情况说明 | BM1: 分公司毛利率 | BN1: 出厂RMB总价合计 | BO1: 重流原因 | BP1: 货柜结构 | BQ1: 出厂价_资金成本 | BR1: 出厂价_退税款 | BS1: 出厂价_实付 | BT1: 出厂价_毛利 | BU1: 出厂价_毛利率 | BV1: 出厂价_分公司毛利 | BW1: 出厂价_分公司毛利率 | BX1: 测价毛利率 | BY1: 是否斯帕克备库 | BZ1: 产品毛利 | CA1: 开发1 | CB1: 产品毛利率 | CC1: 预开船日期 | CD1: 开发2 | CE1: 逾期库存 | CF1: 逾期应收 | CG1: 生产周期 | CH1: 采购合计 | CI1: 信保抬头BR | CJ1: 内陆费计算 | CK1: RMB采购合计 | CL1: 内陆费增减 | CM1: 海运费 | CN1: 库存时间 | CO1: 流程进度 | CP1: 工作流 | CQ1: 关税 | CR1: 与畅想下单对比
A2: 昊特赛三公司 | B2: HSC26X031 | C2: 46174 | D2: 黄家辉 | E2: LPP | F2: 0.2334 | G2: USD | H2: =IFERROR(SUMIFS(畅想出运数据透视!$B$4:$B$500,畅想出运数据透视!$A$4:$A$500,B2),"0") -> 3101.78 | I2: =IFERROR(VLOOKUP(B2,CHOOSE({1,2},畅想出运数据透视!$A$4:$A$500,畅想出运数据透视!$D$4:$D$500),2,FALSE),"") -> 17.34% | L2: 8261.6 | M2: =L2*6.6 -> 54526.56 | N2: =M2*F2 -> 12726.499 | O2: 2026-07-13 | P2: 2026-07-20 | Q2: 2026-07-13 | R2: =MONTH(Q2) -> 7 | S2: 已通过 | T2: 波兰749 | U2: 宁波昊特赛进出口有限公司 | V2: FOB | W2: 100% T/T At sight of B/L copy | X2: 0 | Y2: 待审核 | Z2: 已审核 | AA2: 7564 | AB2: 0 | AC2: 153 | AD2: 1450.67 | AE2: 1338.87 | AF2: 12.7497 | AG2: 0 | AH2: 8261.6 | AI2: 6.6 | AJ2: 0 | AK2: 5193.78 | AL2: 20 | AM2: 50 | AN2: 0 | AO2: 8183.77 | AP2: 57.83 | AQ2: 12606.57 | AR2: PIMLQZ-20260626085 | AT2: 否 | AU2: 2026-06-26 | AV2: 40HQ | AW2: LPP S.A. | AX2: 560.44 | AY2: False | AZ2: 否 | BA2: 办公室 | BB2: 外部工厂 | BC2: 0 | BD2: 0 | BE2: False | BF2: 9340.35 | BG2: False | BI2: 45145.92 | BJ2: 1 | BL2: 无定金 | BM2: 0.1729 | BN2: 45145.92 | BP2: 无 | BQ2: 560.44 | BR2: 5193.78 | BS2: 40845.87 | BT2: 12606.57 | BU2: 0.2334 | BV2: 9340.35 | BW2: 0.1729 | BX2: 0 | BY2: 否 | BZ2: 14574.42 | CA2: False | CB2: 0.26729 | CC2: 2026-07-20 | CD2: False | CE2: 0 | CF2: 0 | CG2: 20 | CH2: 45145.92 | CJ2: 843.73 | CK2: 45145.92 | CL2: 0 | CM2: 0 | CN2: 4 | CO2: 财务-通过 | CP2: 已结束 | CQ2: 0 | CR2: =IF(COUNTIF('畅想下单（外销合同导出）'!$B$2:$B$100,B2)>0,"有","无") -> 有
A3: 昊特赛六公司 | B3: HSE26L009 | C3: 46174 | D3: 林元浩 | E3: HDT ASIA LATAM LIMITED | F3: 0.0936 | G3: USD | H3: =IFERROR(SUMIFS(畅想出运数据透视!$B$4:$B$500,畅想出运数据透视!$A$4:$A$500,B3),"0") -> 0 | I3: =IFERROR(VLOOKUP(B3,CHOOSE({1,2},畅想出运数据透视!$A$4:$A$500,畅想出运数据透视!$D$4:$D$500),2,FALSE),"") | L3: 3104.64 | M3: =L3*6.6 -> 20490.624 | N3: =M3*F3 -> 1917.9224 | O3: 2026-07-30 | P3: 2026-07-31 | Q3: 2026-07-30 | R3: =MONTH(Q3) -> 7 | S3: 已通过 | T3: 墨西哥744 | U3: 宁波昊特赛进出口有限公司 | V3: FOB | W3: 100% T/T At sight of B/L copy | X3: 0 | Y3: 待审核 | Z3: 已审核 | AA3: 2016 | AB3: 0 | AC3: 56 | AD3: 672 | AE3: 616 | AF3: 1.1368 | AG3: 0 | AH3: 3104.64 | AI3: 6.6 | AJ3: 0 | AK3: 2365.68 | AL3: 20 | AM3: 50 | AN3: 0 | AO3: 3062.91 | AP3: 21.73 | AQ3: 1892.44 | AR3: 此票客户发上海保税仓，无港内运杂费等额外费用。且后续会跟其他订单一起进仓 节约运费。 | AS3: PIMLQZ-20260624084 毛利前置流程 | AT3: 否 | AU3: 2026-07-05 | AV3: LCL | AW3: HDT ASIA LATAM LIMITED | AX3: 0 | AY3: False | AZ3: 是 | BA3: 办公室 | BB3: 自拼 | BC3: 0 | BD3: 0 | BE3: False | BF3: 0 | BG3: False | BI3: 20563.2 | BJ3: 1 | BK3: 2026-07-25 | BL3: 无 | BM3: 0 | BN3: 20563.2 | BP3: 保税仓 | BQ3: 0 | BR3: 2365.68 | BS3: 18322.75 | BT3: 1892.44 | BU3: 0.0936 | BV3: 0 | BW3: 0 | BX3: 0 | BY3: 否 | BZ3: 2293.1 | CA3: False | CB3: 0.11191 | CC3: 2026-07-29 | CD3: False | CE3: 0 | CF3: 0 | CG3: 40 | CH3: 20563.2 | CJ3: 75.23 | CK3: 20563.2 | CL3: 0 | CM3: 0 | CN3: -6 | CO3: 财务经理-通过 | CP3: 已结束 | CQ3: 0 | CR3: =IF(COUNTIF('畅想下单（外销合同导出）'!$B$2:$B$100,B3)>0,"有","无") -> 有
A4: 昊特赛六公司 | B4: HSE20L009 | C4: 46174 | D4: 林元浩 | E4: HDT ASIA LATAM LIMITED | F4: 0.0936 | G4: USD | H4: =IFERROR(SUMIFS(畅想出运数据透视!$B$4:$B$500,畅想出运数据透视!$A$4:$A$500,B4),"0") -> 0 | I4: =IFERROR(VLOOKUP(B4,CHOOSE({1,2},畅想出运数据透视!$A$4:$A$500,畅想出运数据透视!$D$4:$D$500),2,FALSE),"") | L4: 3104.64 | M4: =L4*6.6 -> 20490.624 | N4: =M4*F4 -> 1917.9224 | O4: 2026-07-30 | P4: 2026-07-31 | Q4: 2026-07-30 | R4: =MONTH(Q4) -> 7 | S4: 不通过 | T4: 墨西哥744 | U4: 宁波昊特赛进出口有限公司 | V4: FOB | W4: 100% T/T At sight of B/L copy | X4: 0 | Y4: 待审核 | Z4: 待审核 | AA4: 2016 | AB4: 0 | AC4: 56 | AD4: 672 | AE4: 616 | AF4: 1.1368 | AG4: 0 | AH4: 3104.64 | AI4: 6.6 | AJ4: 0 | AK4: 2365.68 | AL4: 20 | AM4: 50 | AN4: 0 | AO4: 3062.91 | AP4: 21.73 | AQ4: 1892.44 | AR4: 此票客户发上海保税仓，无港内运杂费等额外费用。且后续会跟其他订单一起进仓 节约运费。 | AS4: PIMLQZ-20260624084 毛利前置流程 | AT4: 否 | AU4: 2026-06-30 | AV4: LCL | AW4: HDT ASIA LATAM LIMITED | AX4: 0 | AY4: False | AZ4: 是 | BA4: 办公室 | BB4: 自拼 | BC4: 0 | BD4: 0 | BE4: False | BF4: 0 | BG4: False | BI4: 20563.2 | BJ4: 0 | BK4: 2026-07-25 | BL4: 无 | BM4: 0 | BN4: 20563.2 | BP4: 保税仓 | BQ4: 0 | BR4: 2365.68 | BS4: 18322.75 | BT4: 1892.44 | BU4: 0.0936 | BV4: 0 | BW4: 0 | BX4: 0 | BY4: 否 | BZ4: 2293.1 | CA4: False | CB4: 0.11191 | CD4: False | CE4: 0 | CF4: 0 | CG4: 0 | CH4: 20563.2 | CJ4: 75.23 | CK4: 20563.2 | CL4: 0 | CM4: 0 | CN4: 0 | CP4: 未启动 | CQ4: 0 | CR4: =IF(COUNTIF('畅想下单（外销合同导出）'!$B$2:$B$100,B4)>0,"有","无") -> 有
A5: 昊特赛十公司 | B5: HSJ26R005-4 | C5: 46174 | D5: 夏煜昕 | E5: DGL-HT | F5: 0.0855 | G5: USD | H5: =IFERROR(SUMIFS(畅想出运数据透视!$B$4:$B$500,畅想出运数据透视!$A$4:$A$500,B5),"0") -> 108683.5 | I5: =IFERROR(VLOOKUP(B5,CHOOSE({1,2},畅想出运数据透视!$A$4:$A$500,畅想出运数据透视!$D$4:$D$500),2,FALSE),"") -> 15.94% | L5: 109500 | M5: =L5*6.6 -> 722700 | N5: =M5*F5 -> 61790.85 | O5: 2026-07-20 | P5: 2026-07-25 | Q5: 2026-07-20 | R5: =MONTH(Q5) -> 7 | S5: 已通过 | T5: 美国0830 | U5: 宁波昊特赛进出口有限公司 | V5: DDP | W5: 100% T/T Before shipment | X5: 0 | Y5: 待审核 | Z5: 已审核 | AA5: 30000 | AB5: 0 | AC5: 5000 | AD5: 19000 | AE5: 15000 | AF5: 39.5 | AG5: 0 | AH5: 109500 | AI5: 6.6 | AJ5: 0 | AK5: 67300.88 | AL5: 219 | AM5: 50 | AN5: 1000 | AO5: 108514.5 | AP5: 766.5 | AQ5: 61230.98 | AS5: PI毛利前置审批已完成，流程编号：PIMLQZ-20260611078 | AT5: 否 | AU5: 2026-06-22 | AV5: LCL | AX5: 2925 | AY5: False | AZ5: 否 | BA5: 办公室 | BB5: 自拼 | BC5: 0 | BD5: 0 | BE5: False | BF5: 36738.59 | BG5: False | BI5: 585000 | BJ5: 1 | BL5: / | BM5: 0.0513 | BN5: 585000 | BP5: LCL | BQ5: 2925 | BR5: 67300.88 | BS5: 652039.72 | BT5: 61230.98 | BU5: 0.0855 | BV5: 36738.59 | BW5: 0.0513 | BX5: 0 | BY5: 否 | BZ5: 205000.88 | CA5: True | CB5: 0.28366 | CC5: 2026-07-25 | CD5: False | CE5: 0 | CF5: 0 | CG5: 30 | CH5: 585000 | CJ5: 2613.97 | CK5: 585000 | CL5: 130676.63 | CM5: 0 | CN5: 3 | CO5: 财务经理-通过 | CP5: 已结束 | CQ5: 0 | CR5: =IF(COUNTIF('畅想下单（外销合同导出）'!$B$2:$B$100,B5)>0,"有","无") -> 有
A6: 昊特赛三公司 | B6: HSC26X027 | C6: 46174 | D6: 熊环英 | E6: URBAN IMPORTS | F6: 0.2024 | G6: USD | H6: =IFERROR(SUMIFS(畅想出运数据透视!$B$4:$B$500,畅想出运数据透视!$A$4:$A$500,B6),"0") -> 8010.65 | I6: =IFERROR(VLOOKUP(B6,CHOOSE({1,2},畅想出运数据透视!$A$4:$A$500,畅想出运数据透视!$D$4:$D$500),2,FALSE),"") -> 26.04% | L6: 13884 | M6: =L6*6.6 -> 91634.4 | N6: =M6*F6 -> 18546.803 | O6: 2026-07-30 | P6: 2026-07-30 | Q6: 2026-07-30 | R6: =MONTH(Q6) -> 7 | S6: 已通过 | T6: 美国5529 | U6: 宁波昊特赛进出口有限公司 | V6: FOB | W6: OA 60DAYS | X6: 0 | Y6: 待审核 | Z6: 已审核 | AA6: 27360 | AB6: 0 | AC6: 1640 | AD6: 3968.48 | AE6: 3396.48 | AF6: 43.83 | AG6: 0 | AH6: 13884 | AI6: 6.6 | AJ6: 0 | AK6: 8906.96 | AL6: 27.77 | AM6: 50 | AN6: 0 | AO6: 13759.04 | AP6: 97.19 | AQ6: 18380.69 | AS6: PIMLQZ-20260622083 | AT6: 否 | AU6: 2026-06-28 | AV6: 45HQ | AX6: 505.19 | AY6: False | AZ6: 否 | BA6: 客户第一组 | BB6: 自拼 | BC6: 0 | BD6: 458.17 | BE6: False | BF6: 12808.94 | BG6: False | BI6: 77422.08 | BJ6: 2 | BL6: 无 | BM6: 0.1411 | BN6: 77422.08 | BO6: 修改替换工厂 | BP6: 无 | BQ6: 505.19 | BR6: 8906.96 | BS6: 71465.63 | BT6: 18380.69 | BU6: 0.2024 | BV6: 12808.94 | BW6: 0.1411 | BX6: 0 | BY6: 否 | BZ6: 23119.28 | CA6: False | CB6: 0.252299 | CC6: 2026-08-05 | CD6: False | CE6: 0 | CF6: 0 | CG6: 35 | CH6: 77422.08 | CJ6: 2900.51 | CK6: 77422.08 | CL6: 0 | CM6: 0 | CN6: 7 | CO6: 财务-通过 | CP6: 已结束 | CQ6: 0 | CR6: =IF(COUNTIF('畅想下单（外销合同导出）'!$B$2:$B$100,B6)>0,"有","无") -> 有
A7: 昊特赛六公司 | B7: HSE26L008 | C7: 46174 | D7: 林元浩 | E7: LPP | F7: 0.0913 | G7: USD | H7: =IFERROR(SUMIFS(畅想出运数据透视!$B$4:$B$500,畅想出运数据透视!$A$4:$A$500,B7),"0") -> 0 | I7: =IFERROR(VLOOKUP(B7,CHOOSE({1,2},畅想出运数据透视!$A$4:$A$500,畅想出运数据透视!$D$4:$D$500),2,FALSE),"") | L7: 29520 | M7: =L7*6.6 -> 194832 | N7: =M7*F7 -> 17788.162 | O7: 2027-04-13 | P7: 2027-04-19 | Q7: 2027-04-13 | R7: =MONTH(Q7) -> 4 | S7: 已通过 | T7: 波兰749 | U7: 宁波昊特赛进出口有限公司 | V7: FOB | W7: 100% T/T At sight of B/L copy | X7: 0 | Y7: 待审核 | Z7: 已审核 | AA7: 7200 | AB7: 0 | AC7: 1200 | AD7: 7680 | AE7: 6000 | AF7: 65.28 | AG7: 0 | AH7: 29520 | AI7: 6.6 | AJ7: 0 | AK7: 22116.12 | AL7: 59.04 | AM7: 50 | AN7: 0 | AO7: 29254.32 | AP7: 206.64 | AQ7: 17623.43 | AT7: 否 | AU7: 2026-07-15 | AV7: LCL | AW7: LPP S.A. | AX7: 961.2 | AY7: False | AZ7: 否 | BA7: 办公室 | BB7: 自拼 | BC7: 0 | BD7: 0 | BE7: False | BF7: 17623.44 | BG7: True | BI7: 192240 | BJ7: 1 | BL7: 无定金 | BM7: 0.0913 | BN7: 192240 | BP7: 客户自拼LCL | BQ7: 961.2 | BR7: 22116.12 | BS7: 174493.88 | BT7: 17623.43 | BU7: 0.0913 | BV7: 17623.44 | BW7: 0.0913 | BX7: 0 | BY7: 否 | BZ7: 24708.12 | CA7: False | CB7: 0.126818 | CC7: 2027-04-10 | CD7: False | CE7: 0 | CF7: 0 | CG7: 45 | CH7: 192240 | CJ7: 4320 | CK7: 192240 | CL7: 0 | CM7: 0 | CN7: 251 | CO7: 财务经理-通过 | CP7: 已结束 | CQ7: 0 | CR7: =IF(COUNTIF('畅想下单（外销合同导出）'!$B$2:$B$100,B7)>0,"有","无") -> 有
